<sdf version='1.7'>
  <model name='shelf_final'>
    <link name='base_link'>
      <inertial>
        <pose>-0.030933 4.00784 -0.011365 0 -0 0</pose>
        <mass>15769.4</mass>
        <inertia>
          <ixx>74236.4</ixx>
          <ixy>1602.61</ixy>
          <ixz>1401.86</ixz>
          <iyy>1.40458e+06</iyy>
          <iyz>703.014</iyz>
          <izz>1.44711e+06</izz>
        </inertia>
      </inertial>
      <collision name='base_link_collision'>
        <pose>0 0 0 0 -0 0</pose>
        <geometry>
          <mesh>
            <scale>1 1 1</scale>
            <uri>model://shelf_final/meshes/base_link.STL</uri>
          </mesh>
        </geometry>
      </collision>
      <collision name='base_link_fixed_joint_lump__R02_2_collision_1'>
        <pose>0 0 0 0 -0 0</pose>
        <geometry>
          <mesh>
            <scale>1 1 1</scale>
            <uri>model://shelf_final/meshes/R02_2.STL</uri>
          </mesh>
        </geometry>
      </collision>
      <collision name='base_link_fixed_joint_lump__bank1_collision_2'>
        <pose>0 0 0 0 -0 0</pose>
        <geometry>
          <mesh>
            <scale>1 1 1</scale>
            <uri>model://shelf_final/meshes/bank1.STL</uri>
          </mesh>
        </geometry>
      </collision>
      <collision name='base_link_fixed_joint_lump__bank3_collision_3'>
        <pose>0 0 0 0 -0 0</pose>
        <geometry>
          <mesh>
            <scale>1 1 1</scale>
            <uri>model://shelf_final/meshes/bank3.STL</uri>
          </mesh>
        </geometry>
      </collision>
      <collision name='base_link_fixed_joint_lump__bank4_collision_4'>
        <pose>0 0 0 0 -0 0</pose>
        <geometry>
          <mesh>
            <scale>1 1 1</scale>
            <uri>model://shelf_final/meshes/bank4.STL</uri>
          </mesh>
        </geometry>
      </collision>
      <collision name='base_link_fixed_joint_lump__bank2_collision_5'>
        <pose>0 0 0 0 -0 0</pose>
        <geometry>
          <mesh>
            <scale>1 1 1</scale>
            <uri>model://shelf_final/meshes/bank2.STL</uri>
          </mesh>
        </geometry>
      </collision>
      <collision name='base_link_fixed_joint_lump__part7_1_collision_6'>
        <pose>0 0 0 0 -0 0</pose>
        <geometry>
          <mesh>
            <scale>1 1 1</scale>
            <uri>model://shelf_final/meshes/part7_1.STL</uri>
          </mesh>
        </geometry>
      </collision>
      <collision name='base_link_fixed_joint_lump__part7_2_collision_7'>
        <pose>0 0 0 0 -0 0</pose>
        <geometry>
          <mesh>
            <scale>1 1 1</scale>
            <uri>model://shelf_final/meshes/part7_2.STL</uri>
          </mesh>
        </geometry>
      </collision>
      <collision name='base_link_fixed_joint_lump__roof_rack2_collision_8'>
        <pose>0 0 0 0 -0 0</pose>
        <geometry>
          <mesh>
            <scale>1 1 1</scale>
            <uri>model://shelf_final/meshes/roof_rack2.STL</uri>
          </mesh>
        </geometry>
      </collision>
      <collision name='base_link_fixed_joint_lump__roof_rack_collision_9'>
        <pose>0 0 0 0 -0 0</pose>
        <geometry>
          <mesh>
            <scale>1 1 1</scale>
            <uri>model://shelf_final/meshes/roof_rack.STL</uri>
          </mesh>
        </geometry>
      </collision>
      <collision name='base_link_fixed_joint_lump__ss_1_collision_10'>
        <pose>0 0 0 0 -0 0</pose>
        <geometry>
          <mesh>
            <scale>1 1 1</scale>
            <uri>model://shelf_final/meshes/ss_1.STL</uri>
          </mesh>
        </geometry>
      </collision>
      <collision name='base_link_fixed_joint_lump__ss_2_collision_11'>
        <pose>0 0 0 0 -0 0</pose>
        <geometry>
          <mesh>
            <scale>1 1 1</scale>
            <uri>model://shelf_final/meshes/ss_2.STL</uri>
          </mesh>
        </geometry>
      </collision>
      <collision name='base_link_fixed_joint_lump__traction1_collision_12'>
        <pose>0 0 0 0 -0 0</pose>
        <geometry>
          <mesh>
            <scale>1 1 1</scale>
            <uri>model://shelf_final/meshes/traction1.STL</uri>
          </mesh>
        </geometry>
      </collision>
      <collision name='base_link_fixed_joint_lump__traction2_collision_13'>
        <pose>0 0 0 0 -0 0</pose>
        <geometry>
          <mesh>
            <scale>1 1 1</scale>
            <uri>model://shelf_final/meshes/traction2.STL</uri>
          </mesh>
        </geometry>
      </collision>
      <visual name='base_link_visual'>
        <pose>0 0 0 0 -0 0</pose>
        <geometry>
          <mesh>
            <scale>1 1 1</scale>
            <uri>model://shelf_final/meshes/base_link.STL</uri>
          </mesh>
        </geometry>
      </visual>
      <visual name='base_link_fixed_joint_lump__R02_2_visual_1'>
        <pose>0 0 0 0 -0 0</pose>
        <geometry>
          <mesh>
            <scale>1 1 1</scale>
            <uri>model://shelf_final/meshes/R02_2.STL</uri>
          </mesh>
        </geometry>
      </visual>
      <visual name='base_link_fixed_joint_lump__bank1_visual_2'>
        <pose>0 0 0 0 -0 0</pose>
        <geometry>
          <mesh>
            <scale>1 1 1</scale>
            <uri>model://shelf_final/meshes/bank1.STL</uri>
          </mesh>
        </geometry>
      </visual>
      <visual name='base_link_fixed_joint_lump__bank3_visual_3'>
        <pose>0 0 0 0 -0 0</pose>
        <geometry>
          <mesh>
            <scale>1 1 1</scale>
            <uri>model://shelf_final/meshes/bank3.STL</uri>
          </mesh>
        </geometry>
      </visual>
      <visual name='base_link_fixed_joint_lump__bank4_visual_4'>
        <pose>0 0 0 0 -0 0</pose>
        <geometry>
          <mesh>
            <scale>1 1 1</scale>
            <uri>model://shelf_final/meshes/bank4.STL</uri>
          </mesh>
        </geometry>
      </visual>
      <visual name='base_link_fixed_joint_lump__bank2_visual_5'>
        <pose>0 0 0 0 -0 0</pose>
        <geometry>
          <mesh>
            <scale>1 1 1</scale>
            <uri>model://shelf_final/meshes/bank2.STL</uri>
          </mesh>
        </geometry>
      </visual>
      <visual name='base_link_fixed_joint_lump__part7_1_visual_6'>
        <pose>0 0 0 0 -0 0</pose>
        <geometry>
          <mesh>
            <scale>1 1 1</scale>
            <uri>model://shelf_final/meshes/part7_1.STL</uri>
          </mesh>
        </geometry>
      </visual>
      <visual name='base_link_fixed_joint_lump__part7_2_visual_7'>
        <pose>0 0 0 0 -0 0</pose>
        <geometry>
          <mesh>
            <scale>1 1 1</scale>
            <uri>model://shelf_final/meshes/part7_2.STL</uri>
          </mesh>
        </geometry>
      </visual>
      <visual name='base_link_fixed_joint_lump__roof_rack2_visual_8'>
        <pose>0 0 0 0 -0 0</pose>
        <geometry>
          <mesh>
            <scale>1 1 1</scale>
            <uri>model://shelf_final/meshes/roof_rack2.STL</uri>
          </mesh>
        </geometry>
      </visual>
      <visual name='base_link_fixed_joint_lump__roof_rack_visual_9'>
        <pose>0 0 0 0 -0 0</pose>
        <geometry>
          <mesh>
            <scale>1 1 1</scale>
            <uri>model://shelf_final/meshes/roof_rack.STL</uri>
          </mesh>
        </geometry>
      </visual>
      <visual name='base_link_fixed_joint_lump__ss_1_visual_10'>
        <pose>0 0 0 0 -0 0</pose>
        <geometry>
          <mesh>
            <scale>1 1 1</scale>
            <uri>model://shelf_final/meshes/ss_1.STL</uri>
          </mesh>
        </geometry>
      </visual>
      <visual name='base_link_fixed_joint_lump__ss_2_visual_11'>
        <pose>0 0 0 0 -0 0</pose>
        <geometry>
          <mesh>
            <scale>1 1 1</scale>
            <uri>model://shelf_final/meshes/ss_2.STL</uri>
          </mesh>
        </geometry>
      </visual>
      <visual name='base_link_fixed_joint_lump__traction1_visual_12'>
        <pose>0 0 0 0 -0 0</pose>
        <geometry>
          <mesh>
            <scale>1 1 1</scale>
            <uri>model://shelf_final/meshes/traction1.STL</uri>
          </mesh>
        </geometry>
      </visual>
      <visual name='base_link_fixed_joint_lump__traction2_visual_13'>
        <pose>0 0 0 0 -0 0</pose>
        <geometry>
          <mesh>
            <scale>1 1 1</scale>
            <uri>model://shelf_final/meshes/traction2.STL</uri>
          </mesh>
        </geometry>
      </visual>
    </link>
    <joint name='trolley_joint' type='prismatic'>
      <pose relative_to='base_link'>-0.013045 8.8907 -0.036671 0 -0 0</pose>
      <parent>base_link</parent>
      <child>trolley</child>
      <axis>
        <xyz>-1 0 0</xyz>
        <limit>
          <lower>-50</lower>
          <upper>50</upper>
        </limit>
        <dynamics>
          <spring_reference>0</spring_reference>
          <spring_stiffness>0</spring_stiffness>
        </dynamics>
      </axis>
    </joint>
    <link name='trolley'>
      <pose relative_to='trolley_joint'>0 0 0 0 -0 0</pose>
      <inertial>
        <pose>0 0.20546 -0 0 -0 0</pose>
        <mass>3.98</mass>
        <inertia>
          <ixx>24.976</ixx>
          <ixy>1.9995e-16</ixy>
          <ixz>-4.452e-15</ixz>
          <iyy>83.309</iyy>
          <iyz>-4.7011e-16</iyz>
          <izz>64.945</izz>
        </inertia>
      </inertial>
      <collision name='trolley_collision'>
        <pose>0 0 0 0 -0 0</pose>
        <geometry>
          <mesh>
            <scale>1 1 1</scale>
            <uri>model://shelf_final/meshes/trolley.STL</uri>
          </mesh>
        </geometry>
      </collision>
      <visual name='trolley_visual'>
        <pose>0 0 0 0 -0 0</pose>
        <geometry>
          <mesh>
            <scale>1 1 1</scale>
            <uri>model://shelf_final/meshes/trolley.STL</uri>
          </mesh>
        </geometry>
      </visual>
    </link>
    <joint name='carriage_joint' type='prismatic'>
      <pose relative_to='trolley'>0 -4.5358 0 0 -0 0</pose>
      <parent>trolley</parent>
      <child>carriage</child>
      <axis>
        <xyz>0 1 0</xyz>
        <limit>
          <lower>-50</lower>
          <upper>50</upper>
        </limit>
        <dynamics>
          <spring_reference>0</spring_reference>
          <spring_stiffness>0</spring_stiffness>
        </dynamics>
      </axis>
    </joint>
    <link name='carriage'>
      <pose relative_to='carriage_joint'>0 0 0 0 -0 0</pose>
      <inertial>
        <pose>0.041968 0.30521 0.000222 0 -0 0</pose>
        <mass>4.85</mass>
        <inertia>
          <ixx>59.409</ixx>
          <ixy>3.9487e-14</ixy>
          <ixz>1.8761e-14</ixz>
          <iyy>141.75</iyy>
          <iyz>2.0147e-14</iyz>
          <izz>134.72</izz>
        </inertia>
      </inertial>
      <collision name='carriage_collision'>
        <pose>0 0 0 0 -0 0</pose>
        <geometry>
          <mesh>
            <scale>1 1 1</scale>
            <uri>model://shelf_final/meshes/carriage.STL</uri>
          </mesh>
        </geometry>
      </collision>
      <visual name='carriage_visual'>
        <pose>0 0 0 0 -0 0</pose>
        <geometry>
          <mesh>
            <scale>1 1 1</scale>
            <uri>model://shelf_final/meshes/carriage.STL</uri>
          </mesh>
        </geometry>
      </visual>
    </link>
  </model>
</sdf>
