<?xml version="1.0" encoding="utf-8"?>
<!-- This URDF was automatically created by SolidWorks to URDF Exporter! Originally created by Stephen Brawner (brawner@gmail.com) 
     Commit Version: 1.6.0-4-g7f85cfe  Build Version: 1.6.7995.38578
     For more information, please see http://wiki.ros.org/sw_urdf_exporter -->
<robot
  name="AGV6">
  <link
    name="base_link">
    <inertial>
      <origin
        xyz="-0.000123231100652734 0.0553961365561797 0.0171432137554971"
        rpy="0 0 0" />
      <mass
        value="7.19116955235277" />
      <inertia
        ixx="0.441209434736245"
        ixy="-1.27470215918032E-06"
        ixz="-0.00170544512438388"
        iyy="0.654363133888033"
        iyz="-0.00684903683061143"
        izz="0.249410032162092" />
    </inertial>
    <visual>
      <origin
        xyz="0 0 0"
        rpy="0 0 0" />
      <geometry>
        <mesh
          filename="package://AGV6/meshes/base_link.STL" />
      </geometry>
      <material
        name="">
        <color
          rgba="1 1 1 1" />
      </material>
    </visual>
    <collision>
      <origin
        xyz="0 0 0"
        rpy="0 0 0" />
      <geometry>
        <mesh
          filename="package://AGV6/meshes/base_link.STL" />
      </geometry>
    </collision>
  </link>
  <link
    name="DW_L">
    <inertial>
      <origin
        xyz="-2.77555756156289E-17 0 0"
        rpy="0 0 0" />
      <mass
        value="21.1289138446402" />
      <inertia
        ixx="0.0951175890712612"
        ixy="1.19802636067586E-18"
        ixz="4.93597412321146E-20"
        iyy="0.0624867717452084"
        iyz="-4.36538239285748E-08"
        izz="0.0624865212718915" />
    </inertial>
    <visual>
      <origin
        xyz="0 0 0"
        rpy="0 0 0" />
      <geometry>
        <mesh
          filename="package://AGV6/meshes/DW_L.STL" />
      </geometry>
      <material
        name="">
        <color
          rgba="1 0.564705882352941 0.215686274509804 1" />
      </material>
    </visual>
    <collision>
      <origin
        xyz="0 0 0"
        rpy="0 0 0" />
      <geometry>
        <mesh
          filename="package://AGV6/meshes/DW_L.STL" />
      </geometry>
    </collision>
  </link>
  <joint
    name="DW_L_joint"
    type="continuous">
    <origin
      xyz="-0.2315 0 0"
      rpy="0 0 0" />
    <parent
      link="base_link" />
    <child
      link="DW_L" />
    <axis
      xyz="-1 0 0" />
  </joint>
  <link
    name="DW_R">
    <inertial>
      <origin
        xyz="0 -1.38777878078145E-17 8.67361737988404E-19"
        rpy="0 0 0" />
      <mass
        value="21.1289138446402" />
      <inertia
        ixx="0.0951175890712611"
        ixy="1.21294081486111E-18"
        ixz="4.02030780333527E-20"
        iyy="0.0624867745789793"
        iyz="-3.44650850180689E-08"
        izz="0.0624865184381206" />
    </inertial>
    <visual>
      <origin
        xyz="0 0 0"
        rpy="0 0 0" />
      <geometry>
        <mesh
          filename="package://AGV6/meshes/DW_R.STL" />
      </geometry>
      <material
        name="">
        <color
          rgba="1 0.564705882352941 0.215686274509804 1" />
      </material>
    </visual>
    <collision>
      <origin
        xyz="0 0 0"
        rpy="0 0 0" />
      <geometry>
        <mesh
          filename="package://AGV6/meshes/DW_R.STL" />
      </geometry>
    </collision>
  </link>
  <joint
    name="DW_R_joint"
    type="continuous">
    <origin
      xyz="0.2315 0 0"
      rpy="0 0 0" />
    <parent
      link="base_link" />
    <child
      link="DW_R" />
    <axis
      xyz="-1 0 0" />
  </joint>
  <link
    name="CW_mount_lf">
    <inertial>
      <origin
        xyz="6.16173778666962E-15 0.00178317896740091 -3.38618022510673E-15"
        rpy="0 0 0" />
      <mass
        value="0.0356883693504993" />
      <inertia
        ixx="2.08430225591623E-05"
        ixy="4.31146576048056E-21"
        ixz="-4.19953479303227E-21"
        iyy="3.09736689346614E-05"
        iyz="-2.18954881282238E-21"
        izz="1.05474364348081E-05" />
    </inertial>
    <visual>
      <origin
        xyz="0 0 0"
        rpy="0 0 0" />
      <geometry>
        <mesh
          filename="package://AGV6/meshes/CW_mount_lf.STL" />
      </geometry>
      <material
        name="">
        <color
          rgba="1 1 1 1" />
      </material>
    </visual>
    <collision>
      <origin
        xyz="0 0 0"
        rpy="0 0 0" />
      <geometry>
        <mesh
          filename="package://AGV6/meshes/CW_mount_lf.STL" />
      </geometry>
    </collision>
  </link>
  <joint
    name="CW_mount_lf_joint"
    type="fixed">
    <origin
      xyz="-0.23161 0.049 -0.3574"
      rpy="0 0 0" />
    <parent
      link="base_link" />
    <child
      link="CW_mount_lf" />
    <axis
      xyz="0 0 0" />
  </joint>
  <link
    name="CW_brac_lf">
    <inertial>
      <origin
        xyz="2.454957077902E-07 -0.0377750444959561 -0.014330575758621"
        rpy="0 0 0" />
      <mass
        value="0.0747206398188079" />
      <inertia
        ixx="6.84711765656461E-05"
        ixy="-3.66816230357304E-11"
        ixz="6.36578253360279E-12"
        iyy="6.18341101257442E-05"
        iyz="-1.41155279221005E-05"
        izz="8.26659596872355E-05" />
    </inertial>
    <visual>
      <origin
        xyz="0 0 0"
        rpy="0 0 0" />
      <geometry>
        <mesh
          filename="package://AGV6/meshes/CW_brac_lf.STL" />
      </geometry>
      <material
        name="">
        <color
          rgba="1 1 1 1" />
      </material>
    </visual>
    <collision>
      <origin
        xyz="0 0 0"
        rpy="0 0 0" />
      <geometry>
        <mesh
          filename="package://AGV6/meshes/CW_brac_lf.STL" />
      </geometry>
    </collision>
  </link>
  <joint
    name="CW_brac_lf_joint"
    type="continuous">
    <origin
      xyz="0 0 0"
      rpy="0 0 0" />
    <parent
      link="CW_mount_lf" />
    <child
      link="CW_brac_lf" />
    <axis
      xyz="0 1 0" />
  </joint>
  <link
    name="CW_lf">
    <inertial>
      <origin
        xyz="2.77555756156289E-17 0 5.55111512312578E-17"
        rpy="0 0 0" />
      <mass
        value="0.359205022961183" />
      <inertia
        ixx="0.000758344332671333"
        ixy="-2.28486478848757E-19"
        ixz="-6.0425181258677E-18"
        iyy="0.000401507997406102"
        iyz="-1.40478542475118E-19"
        izz="0.000401507997406102" />
    </inertial>
    <visual>
      <origin
        xyz="0 0 0"
        rpy="0 0 0" />
      <geometry>
        <mesh
          filename="package://AGV6/meshes/CW_lf.STL" />
      </geometry>
      <material
        name="">
        <color
          rgba="1 0.968627450980392 0.843137254901961 1" />
      </material>
    </visual>
    <collision>
      <origin
        xyz="0 0 0"
        rpy="0 0 0" />
      <geometry>
        <mesh
          filename="package://AGV6/meshes/CW_lf.STL" />
      </geometry>
    </collision>
  </link>
  <joint
    name="CW_lf_joint"
    type="continuous">
    <origin
      xyz="0 -0.0834999999999897 -0.0300000000000034"
      rpy="0 0 0" />
    <parent
      link="CW_brac_lf" />
    <child
      link="CW_lf" />
    <axis
      xyz="1 0 0" />
  </joint>
  <link
    name="CW_mount_lr">
    <inertial>
      <origin
        xyz="-1.38777878078145E-16 0.00178317896740084 1.66533453693773E-16"
        rpy="0 0 0" />
      <mass
        value="0.0356883693504993" />
      <inertia
        ixx="2.08430225591623E-05"
        ixy="4.31212314465998E-21"
        ixz="-4.19953479303227E-21"
        iyy="3.09736689346614E-05"
        iyz="-2.18956955437884E-21"
        izz="1.05474364348081E-05" />
    </inertial>
    <visual>
      <origin
        xyz="0 0 0"
        rpy="0 0 0" />
      <geometry>
        <mesh
          filename="package://AGV6/meshes/CW_mount_lr.STL" />
      </geometry>
      <material
        name="">
        <color
          rgba="1 1 1 1" />
      </material>
    </visual>
    <collision>
      <origin
        xyz="0 0 0"
        rpy="0 0 0" />
      <geometry>
        <mesh
          filename="package://AGV6/meshes/CW_mount_lr.STL" />
      </geometry>
    </collision>
  </link>
  <joint
    name="CW_mount_lr_joint"
    type="fixed">
    <origin
      xyz="-0.23161 0.049 0.35"
      rpy="0 0 0" />
    <parent
      link="base_link" />
    <child
      link="CW_mount_lr" />
    <axis
      xyz="0 0 0" />
  </joint>
  <link
    name="CW_brac_lr">
    <inertial>
      <origin
        xyz="-2.45495707845711E-07 -0.0377750444959561 0.0143305757586212"
        rpy="0 0 0" />
      <mass
        value="0.0747206398188078" />
      <inertia
        ixx="6.84711765656461E-05"
        ixy="3.66816231089462E-11"
        ixz="6.36578254809412E-12"
        iyy="6.18341101257443E-05"
        iyz="1.41155279221006E-05"
        izz="8.26659596872356E-05" />
    </inertial>
    <visual>
      <origin
        xyz="0 0 0"
        rpy="0 0 0" />
      <geometry>
        <mesh
          filename="package://AGV6/meshes/CW_brac_lr.STL" />
      </geometry>
      <material
        name="">
        <color
          rgba="1 1 1 1" />
      </material>
    </visual>
    <collision>
      <origin
        xyz="0 0 0"
        rpy="0 0 0" />
      <geometry>
        <mesh
          filename="package://AGV6/meshes/CW_brac_lr.STL" />
      </geometry>
    </collision>
  </link>
  <joint
    name="CW_brac_lr_joint"
    type="continuous">
    <origin
      xyz="0 0 0"
      rpy="0 0 0" />
    <parent
      link="CW_mount_lr" />
    <child
      link="CW_brac_lr" />
    <axis
      xyz="0 1 0" />
  </joint>
  <link
    name="CW_lr">
    <inertial>
      <origin
        xyz="-2.77555756156289E-17 0 -5.55111512312578E-17"
        rpy="0 0 0" />
      <mass
        value="0.359205022961183" />
      <inertia
        ixx="0.000758344332671333"
        ixy="-1.86617504521772E-19"
        ixz="-6.01213712701329E-18"
        iyy="0.000401507997406102"
        iyz="-1.45635584494444E-20"
        izz="0.000401507997406102" />
    </inertial>
    <visual>
      <origin
        xyz="0 0 0"
        rpy="0 0 0" />
      <geometry>
        <mesh
          filename="package://AGV6/meshes/CW_lr.STL" />
      </geometry>
      <material
        name="">
        <color
          rgba="1 0.968627450980392 0.843137254901961 1" />
      </material>
    </visual>
    <collision>
      <origin
        xyz="0 0 0"
        rpy="0 0 0" />
      <geometry>
        <mesh
          filename="package://AGV6/meshes/CW_lr.STL" />
      </geometry>
    </collision>
  </link>
  <joint
    name="CW_lr_joint"
    type="continuous">
    <origin
      xyz="0 -0.0835 0.0300000000000003"
      rpy="0 0 0" />
    <parent
      link="CW_brac_lr" />
    <child
      link="CW_lr" />
    <axis
      xyz="1 0 0" />
  </joint>
  <link
    name="CW_mount_rf">
    <inertial>
      <origin
        xyz="6.21724893790088E-15 0.00178317896740087 4.55191440096314E-15"
        rpy="0 0 0" />
      <mass
        value="0.0356883693504993" />
      <inertia
        ixx="2.08430225591623E-05"
        ixy="4.27551920046028E-21"
        ixz="-5.65097827412142E-21"
        iyy="3.09736689346614E-05"
        iyz="-2.12056994969908E-21"
        izz="1.05474364348081E-05" />
    </inertial>
    <visual>
      <origin
        xyz="0 0 0"
        rpy="0 0 0" />
      <geometry>
        <mesh
          filename="package://AGV6/meshes/CW_mount_rf.STL" />
      </geometry>
      <material
        name="">
        <color
          rgba="1 1 1 1" />
      </material>
    </visual>
    <collision>
      <origin
        xyz="0 0 0"
        rpy="0 0 0" />
      <geometry>
        <mesh
          filename="package://AGV6/meshes/CW_mount_rf.STL" />
      </geometry>
    </collision>
  </link>
  <joint
    name="CW_mount_rf_joint"
    type="fixed">
    <origin
      xyz="0.231387499999994 0.0489999999999998 -0.357400000000003"
      rpy="0 0 0" />
    <parent
      link="base_link" />
    <child
      link="CW_mount_rf" />
    <axis
      xyz="0 0 0" />
  </joint>
  <link
    name="CW_brac_rf">
    <inertial>
      <origin
        xyz="2.45495707817955E-07 -0.0377750444959561 -0.0143305757586211"
        rpy="0 0 0" />
      <mass
        value="0.074720639818808" />
      <inertia
        ixx="6.84711765656463E-05"
        ixy="-3.66816230522066E-11"
        ixz="6.36578253920403E-12"
        iyy="6.18341101257445E-05"
        iyz="-1.41155279221006E-05"
        izz="8.26659596872359E-05" />
    </inertial>
    <visual>
      <origin
        xyz="0 0 0"
        rpy="0 0 0" />
      <geometry>
        <mesh
          filename="package://AGV6/meshes/CW_brac_rf.STL" />
      </geometry>
      <material
        name="">
        <color
          rgba="1 1 1 1" />
      </material>
    </visual>
    <collision>
      <origin
        xyz="0 0 0"
        rpy="0 0 0" />
      <geometry>
        <mesh
          filename="package://AGV6/meshes/CW_brac_rf.STL" />
      </geometry>
    </collision>
  </link>
  <joint
    name="CW_brac_rf_joint"
    type="continuous">
    <origin
      xyz="0 0 0"
      rpy="0 0 0" />
    <parent
      link="CW_mount_rf" />
    <child
      link="CW_brac_rf" />
    <axis
      xyz="0 1 0" />
  </joint>
  <link
    name="CW_rf">
    <inertial>
      <origin
        xyz="0 0 0"
        rpy="0 0 0" />
      <mass
        value="0.359205022961183" />
      <inertia
        ixx="0.000758344332671333"
        ixy="-2.36065589915202E-19"
        ixz="-6.09233619691174E-18"
        iyy="0.000401507997406102"
        iyz="1.31258152506491E-20"
        izz="0.000401507997406102" />
    </inertial>
    <visual>
      <origin
        xyz="0 0 0"
        rpy="0 0 0" />
      <geometry>
        <mesh
          filename="package://AGV6/meshes/CW_rf.STL" />
      </geometry>
      <material
        name="">
        <color
          rgba="1 0.968627450980392 0.843137254901961 1" />
      </material>
    </visual>
    <collision>
      <origin
        xyz="0 0 0"
        rpy="0 0 0" />
      <geometry>
        <mesh
          filename="package://AGV6/meshes/CW_rf.STL" />
      </geometry>
    </collision>
  </link>
  <joint
    name="CW_rf_joint"
    type="continuous">
    <origin
      xyz="0 -0.0834999999999898 -0.0300000000000034"
      rpy="0 0 0" />
    <parent
      link="CW_brac_rf" />
    <child
      link="CW_rf" />
    <axis
      xyz="1 0 0" />
  </joint>
  <link
    name="CW_mount_rr">
    <inertial>
      <origin
        xyz="0 0.00178317896740091 -5.55111512312578E-17"
        rpy="0 0 0" />
      <mass
        value="0.0356883693504993" />
      <inertia
        ixx="2.08430225591623E-05"
        ixy="4.42464129229876E-21"
        ixz="-6.43263638029679E-21"
        iyy="3.09736689346613E-05"
        iyz="-1.3481128355295E-21"
        izz="1.05474364348081E-05" />
    </inertial>
    <visual>
      <origin
        xyz="0 0 0"
        rpy="0 0 0" />
      <geometry>
        <mesh
          filename="package://AGV6/meshes/CW_mount_rr.STL" />
      </geometry>
      <material
        name="">
        <color
          rgba="1 1 1 1" />
      </material>
    </visual>
    <collision>
      <origin
        xyz="0 0 0"
        rpy="0 0 0" />
      <geometry>
        <mesh
          filename="package://AGV6/meshes/CW_mount_rr.STL" />
      </geometry>
    </collision>
  </link>
  <joint
    name="CW_mount_rr_joint"
    type="fixed">
    <origin
      xyz="0.23139 0.049 0.35"
      rpy="0 0 0" />
    <parent
      link="base_link" />
    <child
      link="CW_mount_rr" />
    <axis
      xyz="0 0 0" />
  </joint>
  <link
    name="CW_brac_rr">
    <inertial>
      <origin
        xyz="-2.45495707817955E-07 -0.037775044495956 0.0143305757586212"
        rpy="0 0 0" />
      <mass
        value="0.0747206398188077" />
      <inertia
        ixx="6.84711765656461E-05"
        ixy="3.66816230822873E-11"
        ixz="6.36578256634433E-12"
        iyy="6.18341101257445E-05"
        iyz="1.41155279221006E-05"
        izz="8.26659596872357E-05" />
    </inertial>
    <visual>
      <origin
        xyz="0 0 0"
        rpy="0 0 0" />
      <geometry>
        <mesh
          filename="package://AGV6/meshes/CW_brac_rr.STL" />
      </geometry>
      <material
        name="">
        <color
          rgba="1 1 1 1" />
      </material>
    </visual>
    <collision>
      <origin
        xyz="0 0 0"
        rpy="0 0 0" />
      <geometry>
        <mesh
          filename="package://AGV6/meshes/CW_brac_rr.STL" />
      </geometry>
    </collision>
  </link>
  <joint
    name="CW_brac_rr_joint"
    type="continuous">
    <origin
      xyz="0 0 0"
      rpy="0 0 0" />
    <parent
      link="CW_mount_rr" />
    <child
      link="CW_brac_rr" />
    <axis
      xyz="0 1 0" />
  </joint>
  <link
    name="CW_rr">
    <inertial>
      <origin
        xyz="5.55111512312578E-17 5.55111512312578E-17 5.55111512312578E-17"
        rpy="0 0 0" />
      <mass
        value="0.359205022961183" />
      <inertia
        ixx="0.000758344332671333"
        ixy="3.37550549678313E-37"
        ixz="-1.61615581202966E-20"
        iyy="0.000401507997406102"
        iyz="-2.2463716101834E-20"
        izz="0.000401507997406102" />
    </inertial>
    <visual>
      <origin
        xyz="0 0 0"
        rpy="0 0 0" />
      <geometry>
        <mesh
          filename="package://AGV6/meshes/CW_rr.STL" />
      </geometry>
      <material
        name="">
        <color
          rgba="1 0.968627450980392 0.843137254901961 1" />
      </material>
    </visual>
    <collision>
      <origin
        xyz="0 0 0"
        rpy="0 0 0" />
      <geometry>
        <mesh
          filename="package://AGV6/meshes/CW_rr.STL" />
      </geometry>
    </collision>
  </link>
  <joint
    name="CW_rr_joint"
    type="continuous">
    <origin
      xyz="0 -0.0834999999999903 0.0300000000000078"
      rpy="0 0 0" />
    <parent
      link="CW_brac_rr" />
    <child
      link="CW_rr" />
    <axis
      xyz="1 0 0" />
  </joint>
  <link
    name="bot_slider_l">
    <inertial>
      <origin
        xyz="3.00328725344468E-05 -0.020019115440944 -0.00787005515068034"
        rpy="0 0 0" />
      <mass
        value="0.114142227339082" />
      <inertia
        ixx="0.000170720888048912"
        ixy="1.76524939795289E-10"
        ixz="-1.84479169142294E-10"
        iyy="0.000166924082583589"
        iyz="-3.8984499891632E-05"
        izz="0.000103620664781957" />
    </inertial>
    <visual>
      <origin
        xyz="0 0 0"
        rpy="0 0 0" />
      <geometry>
        <mesh
          filename="package://AGV6/meshes/bot_slider_l.STL" />
      </geometry>
      <material
        name="">
        <color
          rgba="1 1 1 1" />
      </material>
    </visual>
    <collision>
      <origin
        xyz="0 0 0"
        rpy="0 0 0" />
      <geometry>
        <mesh
          filename="package://AGV6/meshes/bot_slider_l.STL" />
      </geometry>
    </collision>
  </link>
  <joint
    name="bot_slider_l_joint"
    type="prismatic">
    <origin
      xyz="-0.23161 0.178 -0.38276"
      rpy="0 0 0" />
    <parent
      link="base_link" />
    <child
      link="bot_slider_l" />
    <axis
      xyz="0 0 1" />
    <limit
      lower="-0.07"
      upper="0.04"
      effort="1000000"
      velocity="10" />
  </joint>
  <link
    name="sci_l_A">
    <inertial>
      <origin
        xyz="-0.00320762465783253 0.111617203164123 0.380496275927522"
        rpy="0 0 0" />
      <mass
        value="0.0674706376682142" />
      <inertia
        ixx="0.0033199373554964"
        ixy="-4.90570151355853E-10"
        ixz="-2.83214134038806E-09"
        iyy="0.00307064704258878"
        iyz="-0.000853989130690996"
        izz="0.000565941369655026" />
    </inertial>
    <visual>
      <origin
        xyz="0 0 0"
        rpy="0 0 0" />
      <geometry>
        <mesh
          filename="package://AGV6/meshes/sci_l_A.STL" />
      </geometry>
      <material
        name="">
        <color
          rgba="1 1 1 1" />
      </material>
    </visual>
    <collision>
      <origin
        xyz="0 0 0"
        rpy="0 0 0" />
      <geometry>
        <mesh
          filename="package://AGV6/meshes/sci_l_A.STL" />
      </geometry>
    </collision>
  </link>
  <joint
    name="sci_l_A_joint"
    type="continuous">
    <origin
      xyz="0 0 0"
      rpy="0 0 0" />
    <parent
      link="bot_slider_l" />
    <child
      link="sci_l_A" />
    <axis
      xyz="1 0 0" />
  </joint>
  <link
    name="sci_bot_l">
    <inertial>
      <origin
        xyz="-1.83186799063151E-15 -5.94385651808693E-13 -1.69616047146189E-13"
        rpy="0 0 0" />
      <mass
        value="0.107090296216303" />
      <inertia
        ixx="0.000255203590199193"
        ixy="-1.71390909309625E-21"
        ixz="-1.26953798630974E-17"
        iyy="0.000855782346172711"
        iyz="-6.88000167728881E-21"
        izz="0.000855782346172711" />
    </inertial>
    <visual>
      <origin
        xyz="0 0 0"
        rpy="0 0 0" />
      <geometry>
        <mesh
          filename="package://AGV6/meshes/sci_bot_l.STL" />
      </geometry>
      <material
        name="">
        <color
          rgba="0.647058823529412 0.619607843137255 0.588235294117647 1" />
      </material>
    </visual>
    <collision>
      <origin
        xyz="0 0 0"
        rpy="0 0 0" />
      <geometry>
        <mesh
          filename="package://AGV6/meshes/sci_bot_l.STL" />
      </geometry>
    </collision>
  </link>
  <joint
    name="sci_bot_l_joint"
    type="continuous">
    <origin
      xyz="0 0.11119 0.37903"
      rpy="0 0 0" />
    <parent
      link="sci_l_A" />
    <child
      link="sci_bot_l" />
    <axis
      xyz="1 0 0" />
  </joint>
  <link
    name="sci_l_B">
    <inertial>
      <origin
        xyz="0.00320762465782592 0.000429416082116801 -0.00146820836070355"
        rpy="0 0 0" />
      <mass
        value="0.0674706376682141" />
      <inertia
        ixx="0.0033199373554964"
        ixy="4.90570151483658E-10"
        ixz="-2.83214133914357E-09"
        iyy="0.00307064704258878"
        iyz="0.000853989130690997"
        izz="0.000565941369655027" />
    </inertial>
    <visual>
      <origin
        xyz="0 0 0"
        rpy="0 0 0" />
      <geometry>
        <mesh
          filename="package://AGV6/meshes/sci_l_B.STL" />
      </geometry>
      <material
        name="">
        <color
          rgba="1 1 1 1" />
      </material>
    </visual>
    <collision>
      <origin
        xyz="0 0 0"
        rpy="0 0 0" />
      <geometry>
        <mesh
          filename="package://AGV6/meshes/sci_l_B.STL" />
      </geometry>
    </collision>
  </link>
  <joint
    name="sci_l_B_joint"
    type="continuous">
    <origin
      xyz="0 0 0"
      rpy="0 0 0" />
    <parent
      link="sci_bot_l" />
    <child
      link="sci_l_B" />
    <axis
      xyz="1 0 0" />
  </joint>

<!-- Gazebo tag to close the loop-->
<gazebo>
    <joint name='virtual_base_l_joint' type='revolute'>
      <pose relative_to='sci_l_B'>0 -0.19607 0.3429 0 -0 0</pose>
      <parent>sci_l_B</parent>
      <child>base_link</child>
      <axis>
        <xyz>1 0 0</xyz>
        <limit>
          <lower>-10</lower>
          <upper>10</upper>
        </limit>
        <dynamics>
          <spring_reference>0</spring_reference>
          <spring_stiffness>0</spring_stiffness>
          <friction>0.01</friction>
          <damping>0.01</damping>
        </dynamics>
      </axis>
    </joint>
</gazebo>

  <link
    name="top_fixed_l_A">
    <inertial>
      <origin
        xyz="2.9917997246276E-08 0.0292682220375312 -9.63423080202475E-09"
        rpy="0 0 0" />
      <mass
        value="0.0175464674455898" />
      <inertia
        ixx="0.000145636754929182"
        ixy="-1.17278497681385E-10"
        ixz="-3.14519748340529E-11"
        iyy="0.000117199630744032"
        iyz="3.32238392767131E-11"
        izz="0.000198823734012958" />
    </inertial>
    <visual>
      <origin
        xyz="0 0 0"
        rpy="0 0 0" />
      <geometry>
        <mesh
          filename="package://AGV6/meshes/top_fixed_l_A.STL" />
      </geometry>
      <material
        name="">
        <color
          rgba="1 1 1 1" />
      </material>
    </visual>
    <collision>
      <origin
        xyz="0 0 0"
        rpy="0 0 0" />
      <geometry>
        <mesh
          filename="package://AGV6/meshes/top_fixed_l_A.STL" />
      </geometry>
    </collision>
  </link>
  <joint
    name="top_fixed_l_A_joint"
    type="continuous">
    <origin
      xyz="0 0.222375574164177 0.758056135133486"
      rpy="0 0 0" />
    <parent
      link="sci_l_A" />
    <child
      link="top_fixed_l_A" />
    <axis
      xyz="1 0 0" />
  </joint>
  <link
    name="top_fixed_l_B">
    <inertial>
      <origin
        xyz="9.61248070030507E-09 0.0292682220267282 2.99167065009875E-08"
        rpy="0 0 0" />
      <mass
        value="0.0175464674455898" />
      <inertia
        ixx="0.000198823734012958"
        ixy="-3.32238427047802E-11"
        ixz="3.14519747222919E-11"
        iyy="0.000117199630744032"
        iyz="-1.17278497739316E-10"
        izz="0.000145636754929182" />
    </inertial>
    <visual>
      <origin
        xyz="0 0 0"
        rpy="0 0 0" />
      <geometry>
        <mesh
          filename="package://AGV6/meshes/top_fixed_l_B.STL" />
      </geometry>
      <material
        name="">
        <color
          rgba="1 1 1 1" />
      </material>
    </visual>
    <collision>
      <origin
        xyz="0 0 0"
        rpy="0 0 0" />
      <geometry>
        <mesh
          filename="package://AGV6/meshes/top_fixed_l_B.STL" />
      </geometry>
    </collision>
  </link>
  <joint
    name="top_fixed_l_B_joint"
    type="continuous">
    <origin
      xyz="0 0.0700000000108058 0"
      rpy="0 0 0" />
    <parent
      link="top_fixed_l_A" />
    <child
      link="top_fixed_l_B" />
    <axis
      xyz="0 0 -1" />
  </joint>
  <link
    name="TM_base">
    <inertial>
      <origin
        xyz="0.291868121786296 0.0175685442182614 -0.370862486470708"
        rpy="0 0 0" />
      <mass
        value="0.0841981200967215" />
      <inertia
        ixx="0.523004037616227"
        ixy="1.43308185415945E-06"
        ixz="-7.44855697234436E-07"
        iyy="0.791444525751443"
        iyz="3.47328697894301E-07"
        izz="0.282393332443741" />
    </inertial>
    <visual>
      <origin
        xyz="0 0 0"
        rpy="0 0 0" />
      <geometry>
        <mesh
          filename="package://AGV6/meshes/TM_base.STL" />
      </geometry>
      <material
        name="">
        <color
          rgba="1 1 1 1" />
      </material>
    </visual>
    <collision>
      <origin
        xyz="0 0 0"
        rpy="0 0 0" />
      <geometry>
        <mesh
          filename="package://AGV6/meshes/TM_base.STL" />
      </geometry>
    </collision>
  </link>
  <joint
    name="TM_base_joint"
    type="continuous">
    <origin
      xyz="0 0.0699999999892545 0"
      rpy="0 0 0" />
    <parent
      link="top_fixed_l_B" />
    <child
      link="TM_base" />
    <axis
      xyz="0 0 -1" />
  </joint>
  <link
    name="top_slider_l">
    <inertial>
      <origin
        xyz="-6.59516885548328E-12 -1.03062003375953E-12 -2.49858467249453E-12"
        rpy="0 0 0" />
      <mass
        value="0.0534640164778728" />
      <inertia
        ixx="0.0126331366475046"
        ixy="7.37693456618301E-22"
        ixz="-3.90232459437347E-18"
        iyy="0.0126331366475046"
        iyz="2.45615615898512E-18"
        izz="4.24137711150283E-05" />
    </inertial>
    <visual>
      <origin
        xyz="0 0 0"
        rpy="0 0 0" />
      <geometry>
        <mesh
          filename="package://AGV6/meshes/top_slider_l.STL" />
      </geometry>
      <material
        name="">
        <color
          rgba="0.647058823529412 0.619607843137255 0.588235294117647 1" />
      </material>
    </visual>
    <collision>
      <origin
        xyz="0 0 0"
        rpy="0 0 0" />
      <geometry>
        <mesh
          filename="package://AGV6/meshes/top_slider_l.STL" />
      </geometry>
    </collision>
  </link>
  <joint
    name="top_slider_l_joint"
    type="continuous">
    <origin
      xyz="0 0 -0.577999999999855"
      rpy="0 0 0" />
    <parent
      link="TM_base" />
    <child
      link="top_slider_l" />
    <axis
      xyz="0 0 1" />
  </joint>
  <link
    name="top_slider_l_B">
    <inertial>
      <origin
        xyz="4.28832247489908E-11 -0.0333359298342344 2.43138842392909E-13"
        rpy="0 0 0" />
      <mass
        value="0.0272837758042886" />
      <inertia
        ixx="0.000197252502105011"
        ixy="-3.48571744691588E-18"
        ixz="-4.02849069257547E-14"
        iyy="0.000224313595989507"
        iyz="1.54054474519612E-19"
        izz="0.000136574041354006" />
    </inertial>
    <visual>
      <origin
        xyz="0 0 0"
        rpy="0 0 0" />
      <geometry>
        <mesh
          filename="package://AGV6/meshes/top_slider_l_B.STL" />
      </geometry>
      <material
        name="">
        <color
          rgba="1 1 1 1" />
      </material>
    </visual>
    <collision>
      <origin
        xyz="0 0 0"
        rpy="0 0 0" />
      <geometry>
        <mesh
          filename="package://AGV6/meshes/top_slider_l_B.STL" />
      </geometry>
    </collision>
  </link>
  <joint
    name="top_slider_l_B_joint"
    type="prismatic">
    <origin
      xyz="0 0 -0.180056135137549"
      rpy="0 0 0" />
    <parent
      link="top_slider_l" />
    <child
      link="top_slider_l_B" />
    <axis
      xyz="0 0 1" />
    <limit
      lower="-1"
      upper="1"
      effort="1000000"
      velocity="10" />
    <dynamics damping="0.01" friction="0.01"/>
  </joint>
  <link
    name="top_slider_l_A">
    <inertial>
      <origin
        xyz="2.9958696107224E-08 -0.0407317779445758 -9.6348778400035E-09"
        rpy="0 0 0" />
      <mass
        value="0.0175464674455898" />
      <inertia
        ixx="0.000145636754929182"
        ixy="-1.17278497689106E-10"
        ixz="-3.14519736372876E-11"
        iyy="0.000117199630744032"
        iyz="3.32238394208671E-11"
        izz="0.000198823734012958" />
    </inertial>
    <visual>
      <origin
        xyz="0 0 0"
        rpy="0 0 0" />
      <geometry>
        <mesh
          filename="package://AGV6/meshes/top_slider_l_A.STL" />
      </geometry>
      <material
        name="">
        <color
          rgba="1 1 1 1" />
      </material>
    </visual>
    <collision>
      <origin
        xyz="0 0 0"
        rpy="0 0 0" />
      <geometry>
        <mesh
          filename="package://AGV6/meshes/top_slider_l_A.STL" />
      </geometry>
    </collision>
  </link>
  <joint
    name="top_slider_l_A_joint"
    type="continuous">
    <origin
      xyz="0 -0.0699999999999998 0"
      rpy="0 0 0" />
    <parent
      link="top_slider_l_B" />
    <child
      link="top_slider_l_A" />
    <axis
      xyz="0 0 -1" />
  </joint>

<!-- Gazebo tag to close the loop-->
<gazebo>
    <joint name='virtual_sci_l_1_joint' type='revolute'>
      <pose relative_to='top_slider_l_A'>0 -0.07 0 0 -0 0</pose>
      <parent>top_slider_l_A</parent>
      <child>sci_l_B</child>
      <axis>
        <xyz>1 0 0</xyz>
        <limit>
          <lower>-1</lower>
          <upper>1</upper>
        </limit>
        <dynamics>
          <spring_reference>0</spring_reference>
          <spring_stiffness>0</spring_stiffness>
          <friction>0.01</friction>
          <damping>0.01</damping>
        </dynamics>
      </axis>
    </joint>
</gazebo>

  <link
    name="top_slider_r">
    <inertial>
      <origin
        xyz="-9.01556607146858E-13 -1.35136346557374E-12 -2.44718134645439E-12"
        rpy="0 0 0" />
      <mass
        value="0.0534640164778729" />
      <inertia
        ixx="0.0126331366475046"
        ixy="-4.66467826933965E-22"
        ixz="1.29774914558228E-17"
        iyy="0.0126331366475046"
        iyz="2.93233862256667E-18"
        izz="4.24137711150283E-05" />
    </inertial>
    <visual>
      <origin
        xyz="0 0 0"
        rpy="0 0 0" />
      <geometry>
        <mesh
          filename="package://AGV6/meshes/top_slider_r.STL" />
      </geometry>
      <material
        name="">
        <color
          rgba="0.647058823529412 0.619607843137255 0.588235294117647 1" />
      </material>
    </visual>
    <collision>
      <origin
        xyz="0 0 0"
        rpy="0 0 0" />
      <geometry>
        <mesh
          filename="package://AGV6/meshes/top_slider_r.STL" />
      </geometry>
    </collision>
  </link>
  <joint
    name="top_slider_r_joint"
    type="continuous">
    <origin
      xyz="0.462999999999631 0 -0.527999999999904"
      rpy="0 0 0" />
    <parent
      link="TM_base" />
    <child
      link="top_slider_r" />
    <axis
      xyz="0 0 1" />
  </joint>
  <link
    name="top_slider_mount_r">
    <inertial>
      <origin
        xyz="-2.74169575931182E-12 -0.0333359298565404 5.38702416008618E-12"
        rpy="0 0 0" />
      <mass
        value="0.0272837757765887" />
      <inertia
        ixx="0.000131331237884416"
        ixy="3.40936197630362E-15"
        ixz="-4.30217048697025E-15"
        iyy="0.000224313595891299"
        iyz="-1.20389705903845E-15"
        izz="0.000202495305461991" />
    </inertial>
    <visual>
      <origin
        xyz="0 0 0"
        rpy="0 0 0" />
      <geometry>
        <mesh
          filename="package://AGV6/meshes/top_slider_mount_r.STL" />
      </geometry>
      <material
        name="">
        <color
          rgba="1 1 1 1" />
      </material>
    </visual>
    <collision>
      <origin
        xyz="0 0 0"
        rpy="0 0 0" />
      <geometry>
        <mesh
          filename="package://AGV6/meshes/top_slider_mount_r.STL" />
      </geometry>
    </collision>
  </link>
  <joint
    name="top_slider_mount_r_joint"
    type="prismatic">
    <origin
      xyz="0 0 -0.205904982702463"
      rpy="0 0 0" />
    <parent
      link="top_slider_r" />
    <child
      link="top_slider_mount_r" />
    <axis
      xyz="0 0 1" />
    <limit
      lower="-1"
      upper="1"
      effort="1000000"
      velocity="10" />
    <dynamics damping="0.01" friction="0.01"/>
  </joint>

<!-- Gazebo tag to close the loop-->
<gazebo>
    <joint name='virtual_sci_r_1_joint' type='revolute'>
      <pose relative_to='top_slider_mount_r'>0 -0.07 0 0 -0 0</pose>
      <parent>top_slider_mount_r</parent>
      <child>sci_r_B</child>
      <axis>
        <xyz>-1 0 0</xyz>
        <limit>
          <lower>-1</lower>
          <upper>1</upper>
        </limit>
        <dynamics>
          <spring_reference>0</spring_reference>
          <spring_stiffness>0</spring_stiffness>
          <friction>0.01</friction>
          <damping>0.01</damping>
        </dynamics>
      </axis>
    </joint>
</gazebo>

  <link
    name="top_fixed_mount_r">
    <inertial>
      <origin
        xyz="2.99144455317979E-08 -0.0407317779625282 -9.6375042391017E-09"
        rpy="0 0 0" />
      <mass
        value="0.0175464674455898" />
      <inertia
        ixx="0.000145636754929182"
        ixy="-1.17278497847317E-10"
        ixz="-3.14519748085906E-11"
        iyy="0.000117199630744032"
        iyz="3.3223839335281E-11"
        izz="0.000198823734012958" />
    </inertial>
    <visual>
      <origin
        xyz="0 0 0"
        rpy="0 0 0" />
      <geometry>
        <mesh
          filename="package://AGV6/meshes/top_fixed_mount_r.STL" />
      </geometry>
      <material
        name="">
        <color
          rgba="1 1 1 1" />
      </material>
    </visual>
    <collision>
      <origin
        xyz="0 0 0"
        rpy="0 0 0" />
      <geometry>
        <mesh
          filename="package://AGV6/meshes/top_fixed_mount_r.STL" />
      </geometry>
    </collision>
  </link>
  <joint
    name="top_fixed_mount_r_joint"
    type="continuous">
    <origin
      xyz="0.463 0 0"
      rpy="0 0 0" />
    <parent
      link="TM_base" />
    <child
      link="top_fixed_mount_r" />
    <axis
      xyz="0 0 -1" />
  </joint>

<!-- Gazebo tag to close the loop-->
<gazebo>
    <joint name='virtual_sci_r_2_joint' type='revolute'>
      <pose relative_to='top_fixed_mount_r'>0 -0.07 0 0 -0 0</pose>
      <parent>top_fixed_mount_r</parent>
      <child>sci_r_A</child>
      <axis>
        <xyz>-1 0 0</xyz>
        <limit>
          <lower>-1</lower>
          <upper>1</upper>
        </limit>
        <dynamics>
          <spring_reference>0</spring_reference>
          <spring_stiffness>0</spring_stiffness>
          <friction>0.01</friction>
          <damping>0.01</damping>
        </dynamics>
      </axis>
    </joint>
</gazebo>

  <link
    name="TM_slider">
    <inertial>
      <origin
        xyz="-0.000173317609121537 0.0199075028253252 0.552499634711138"
        rpy="0 0 0" />
      <mass
        value="0.0646005820446419" />
      <inertia
        ixx="0.000659085084843268"
        ixy="1.86242489650704E-15"
        ixz="-2.50846915190889E-08"
        iyy="0.0016710542180811"
        iyz="1.91177837579774E-15"
        izz="0.00169043516399453" />
    </inertial>
    <visual>
      <origin
        xyz="0 0 0"
        rpy="0 0 0" />
      <geometry>
        <mesh
          filename="package://AGV6/meshes/TM_slider.STL" />
      </geometry>
      <material
        name="">
        <color
          rgba="1 1 1 1" />
      </material>
    </visual>
    <collision>
      <origin
        xyz="0 0 0"
        rpy="0 0 0" />
      <geometry>
        <mesh
          filename="package://AGV6/meshes/TM_slider.STL" />
      </geometry>
    </collision>
  </link>
  <joint
    name="TM_slider_joint"
    type="prismatic">
    <origin
      xyz="0.435819538739194 -0.0111946676043577 -0.927500012812989"
      rpy="0 0 0" />
    <parent
      link="TM_base" />
    <child
      link="TM_slider" />
    <axis
      xyz="-1 0 0" />
    <limit
      lower="0"
      upper="0.41"
      effort="10"
      velocity="0.5" />
  </joint>
  <link
    name="TM_loader">
    <inertial>
      <origin
        xyz="0.139668364646949 0.104939992942462 0.63474946962643"
        rpy="0 0 0" />
      <mass
        value="0.166983722284314" />
      <inertia
        ixx="0.0102638416668858"
        ixy="-0.000244988085988281"
        ixz="1.08674263799754E-16"
        iyy="0.0104058329221927"
        iyz="-9.79598271076178E-17"
        izz="0.000530782397838516" />
    </inertial>
    <visual>
      <origin
        xyz="0 0 0"
        rpy="0 0 0" />
      <geometry>
        <mesh
          filename="package://AGV6/meshes/TM_loader.STL" />
      </geometry>
      <material
        name="">
        <color
          rgba="1 1 1 1" />
      </material>
    </visual>
    <collision>
      <origin
        xyz="0 0 0"
        rpy="0 0 0" />
      <geometry>
        <mesh
          filename="package://AGV6/meshes/TM_loader.STL" />
      </geometry>
    </collision>
  </link>
  <joint
    name="TM_loader_joint"
    type="revolute">
    <origin
      xyz="-0.0450000026110648 -0.0218053351926358 -0.0822500000025603"
      rpy="0 0 0" />
    <parent
      link="TM_slider" />
    <child
      link="TM_loader" />
    <axis
      xyz="0 0 1" />
    <limit
      lower="-1.5"
      upper="0.3"
      effort="5"
      velocity="0.5" />
  </joint>
  <link
    name="bot_slider_r">
    <inertial>
      <origin
        xyz="3.00329703398772E-05 -0.0200191157568334 -0.00787005509840338"
        rpy="0 0 0" />
      <mass
        value="0.0114142226241279" />
      <inertia
        ixx="0.000170720888038368"
        ixy="1.76189662824187E-10"
        ixz="-1.84160264768761E-10"
        iyy="0.000166924082186474"
        iyz="-3.89844998895538E-05"
        izz="0.000103620664324206" />
    </inertial>
    <visual>
      <origin
        xyz="0 0 0"
        rpy="0 0 0" />
      <geometry>
        <mesh
          filename="package://AGV6/meshes/bot_slider_r.STL" />
      </geometry>
      <material
        name="">
        <color
          rgba="1 1 1 1" />
      </material>
    </visual>
    <collision>
      <origin
        xyz="0 0 0"
        rpy="0 0 0" />
      <geometry>
        <mesh
          filename="package://AGV6/meshes/bot_slider_r.STL" />
      </geometry>
    </collision>
  </link>
  <joint
    name="bot_slider_r_joint"
    type="prismatic">
    <origin
      xyz="0.231387499999987 0.178000000000173 -0.358604982699973"
      rpy="0 0 0" />
    <parent
      link="base_link" />
    <child
      link="bot_slider_r" />
    <axis
      xyz="0 0 -1" />
    <limit
      lower="-0.05"
      upper="0.088"
      effort="1000000"
      velocity="10" />
    <dynamics damping="0.01" friction="0.01"/>
  </joint>
  <link
    name="sci_r_A">
    <inertial>
      <origin
        xyz="-0.00320762465783253 0.146752785281717 0.368374043668746"
        rpy="0 0 0" />
      <mass
        value="0.0674706376682145" />
      <inertia
        ixx="0.0033199373554964"
        ixy="-7.535888266427E-10"
        ixz="-2.7737677491446E-09"
        iyy="0.00288947360138284"
        iyz="-0.00107250163893273"
        izz="0.000747114810860961" />
    </inertial>
    <visual>
      <origin
        xyz="0 0 0"
        rpy="0 0 0" />
      <geometry>
        <mesh
          filename="package://AGV6/meshes/sci_r_A.STL" />
      </geometry>
      <material
        name="">
        <color
          rgba="1 1 1 1" />
      </material>
    </visual>
    <collision>
      <origin
        xyz="0 0 0"
        rpy="0 0 0" />
      <geometry>
        <mesh
          filename="package://AGV6/meshes/sci_r_A.STL" />
      </geometry>
    </collision>
  </link>
  <joint
    name="sci_r_A_joint"
    type="continuous">
    <origin
      xyz="0 0 0"
      rpy="0 0 0" />
    <parent
      link="bot_slider_r" />
    <child
      link="sci_r_A" />
    <axis
      xyz="-1 0 0" />
  </joint>
  <link
    name="sci_bolt_r">
    <inertial>
      <origin
        xyz="5.55111512312578E-16 -5.78675996010247E-13 -2.14368453543834E-13"
        rpy="0 0 0" />
      <mass
        value="0.107090296216303" />
      <inertia
        ixx="0.000255203590199193"
        ixy="-1.66299006494693E-21"
        ixz="-1.27432952590575E-17"
        iyy="0.000855782346172711"
        iyz="-1.92167870212296E-20"
        izz="0.000855782346172711" />
    </inertial>
    <visual>
      <origin
        xyz="0 0 0"
        rpy="0 0 0" />
      <geometry>
        <mesh
          filename="package://AGV6/meshes/sci_bolt_r.STL" />
      </geometry>
      <material
        name="">
        <color
          rgba="0.647058823529412 0.619607843137255 0.588235294117647 1" />
      </material>
    </visual>
    <collision>
      <origin
        xyz="0 0 0"
        rpy="0 0 0" />
      <geometry>
        <mesh
          filename="package://AGV6/meshes/sci_bolt_r.STL" />
      </geometry>
    </collision>
  </link>
  <joint
    name="sci_bolt_r_joint"
    type="continuous">
    <origin
      xyz="0 0.146187787082068 0.366952491349931"
      rpy="0 0 0" />
    <parent
      link="sci_r_A" />
    <child
      link="sci_bolt_r" />
    <axis
      xyz="1 0 0" />
  </joint>
  <link
    name="sci_r_B">
    <inertial>
      <origin
        xyz="0.00320762465782382 0.000564998199637928 -0.00142155231942795"
        rpy="0 0 0" />
      <mass
        value="0.0674706376682141" />
      <inertia
        ixx="0.0033199373554964"
        ixy="7.53588826311276E-10"
        ixz="-2.77376774934242E-09"
        iyy="0.00288947360138459"
        iyz="0.00107250163893098"
        izz="0.000747114810859211" />
    </inertial>
    <visual>
      <origin
        xyz="0 0 0"
        rpy="0 0 0" />
      <geometry>
        <mesh
          filename="package://AGV6/meshes/sci_r_B.STL" />
      </geometry>
      <material
        name="">
        <color
          rgba="1 1 1 1" />
      </material>
    </visual>
    <collision>
      <origin
        xyz="0 0 0"
        rpy="0 0 0" />
      <geometry>
        <mesh
          filename="package://AGV6/meshes/sci_r_B.STL" />
      </geometry>
    </collision>
  </link>
  <joint
    name="sci_r_B_joint"
    type="continuous">
    <origin
      xyz="0 0 0"
      rpy="0 0 0" />
    <parent
      link="sci_bolt_r" />
    <child
      link="sci_r_B" />
    <axis
      xyz="1 0 0" />
  </joint>


<!-- Gazebo tag to close the loop-->
<gazebo>
    <joint name='virtual_base_r_joint' type='revolute'>
      <pose relative_to='sci_r_B'>0 -0.231068 0.320363 0 -0 0</pose>
      <parent>sci_r_B</parent>
      <child>base_link</child>
      <axis>
        <xyz>-1 0 0</xyz>
        <limit>
          <lower>-1</lower>
          <upper>1</upper>
        </limit>
        <dynamics>
          <spring_reference>0</spring_reference>
          <spring_stiffness>0</spring_stiffness>
          <friction>0.01</friction>
          <damping>0.01</damping>
        </dynamics>
      </axis>
    </joint>
</gazebo>

<!-- Plugins and controllers-->

<!-- Differential drive plugin-->
<gazebo>
    <plugin name='differential_drive_controller' filename='libgazebo_ros_diff_drive.so'>
      <update_rate>50</update_rate>
      <left_joint>DW_L_joint</left_joint>
      <right_joint>DW_R_joint</right_joint>
      <wheel_separation>0.465</wheel_separation>
      <wheel_diameter>0.097</wheel_diameter>
      <max_wheel_acceleration>1.0</max_wheel_acceleration>
      <max_wheel_torque>20</max_wheel_torque>
      <odometry_topic>odom</odometry_topic>
      <odometry_frame>odom</odometry_frame>
      <robot_base_frame>base_footprint</robot_base_frame>
      <publish_odom>1</publish_odom>
      <publish_odom_tf>1</publish_odom_tf>
      <publish_wheel_tf>1</publish_wheel_tf>
    </plugin>
</gazebo>

<!-- ROS2 controller part:Package used: Gazebo_ros2_control, branch: humble -->
  <ros2_control name="GazeboSystem" type="system">
    <hardware>
      <plugin>gazebo_ros2_control/GazeboSystem</plugin>
    </hardware>


    <!-- For each moving joint define a command interface and state interfaces based on the controllers-->

    <!-- For lifting and tilting: bot sliders l and r-->
    <joint name="bot_slider_l_joint">
      <command_interface name="velocity">
        <param name="min">-10</param>
        <param name="max">10</param>
      </command_interface>
      <state_interface name="position"/>
      <state_interface name="velocity"/>
      <state_interface name="effort"/>
    </joint>

    <joint name="bot_slider_r_joint">
      <command_interface name="velocity">
        <param name="min">-10</param>
        <param name="max">10</param>
      </command_interface>
      <state_interface name="position"/>
      <state_interface name="velocity"/>
      <state_interface name="effort"/>
    </joint>

    <!-- For unloading and loading of the totes: TM_slider and loader-->
    <joint name="TM_slider_joint">
      <command_interface name="velocity">
        <param name="min">-10</param>
        <param name="max">10</param>
      </command_interface>
      <state_interface name="position"/>
      <state_interface name="velocity"/>
      <state_interface name="effort"/>
    </joint>

    <joint name="TM_loader_joint">
      <command_interface name="velocity">
        <param name="min">-10</param>
        <param name="max">10</param>
      </command_interface>
      <state_interface name="position"/>
      <state_interface name="velocity"/>
      <state_interface name="effort"/>
    </joint>

    <!-- extra imu sensor from the demo example-->
    <sensor name="cart_imu_sensor">
      <state_interface name="orientation.x"/>
      <state_interface name="orientation.y"/>
      <state_interface name="orientation.z"/>
      <state_interface name="orientation.w"/>
      <state_interface name="angular_velocity.x"/>
      <state_interface name="angular_velocity.y"/>
      <state_interface name="angular_velocity.z"/>
      <state_interface name="linear_acceleration.x"/>
      <state_interface name="linear_acceleration.y"/>
      <state_interface name="linear_acceleration.z"/>
    </sensor>
  </ros2_control>

<!-- Gazebo_ros2_control plugin: here need to specify the path for the configuration file-->
  <gazebo>
    <plugin filename="libgazebo_ros2_control.so" name="gazebo_ros2_control">
      <parameters>$(find my_agv2)/config/agv5_controller.yaml</parameters>
    </plugin>
  </gazebo>

</robot>