<sdf version='1.7'>
  <model name='AGV5'>
    <link name='base_link'>
      <inertial>
        <pose>-0.000123 0.055306 0.016738 0 -0 0</pose>
        <mass>57.33392</mass>
        <inertia>
          <ixx>0.459216</ixx>
          <ixy>-1.26697e-06</ixy>
          <ixz>-0.00170541</ixz>
          <iyy>0.680057</iyy>
          <iyz>-0.0068625</iyz>
          <izz>0.257106</izz>
        </inertia>
      </inertial>
      <collision name='base_link_collision'>
        <pose>0 0 0 0 -0 0</pose>
        <geometry>
          <mesh>
            <scale>1 1 1</scale>
            <uri>model://AGV5/meshes/base_link.STL</uri>
          </mesh>
        </geometry>
      </collision>
      <collision name='base_link_fixed_joint_lump__CW_mount_lf_collision_1'>
        <pose>-0.23161 0.049 -0.3574 0 -0 0</pose>
        <geometry>
          <mesh>
            <scale>1 1 1</scale>
            <uri>model://AGV5/meshes/CW_mount_lf.STL</uri>
          </mesh>
        </geometry>
      </collision>
      <collision name='base_link_fixed_joint_lump__CW_mount_lr_collision_2'>
        <pose>-0.23161 0.049 0.35 0 -0 0</pose>
        <geometry>
          <mesh>
            <scale>1 1 1</scale>
            <uri>model://AGV5/meshes/CW_mount_lr.STL</uri>
          </mesh>
        </geometry>
      </collision>
      <collision name='base_link_fixed_joint_lump__CW_mount_rf_collision_3'>
        <pose>0.231387 0.049 -0.3574 0 -0 0</pose>
        <geometry>
          <mesh>
            <scale>1 1 1</scale>
            <uri>model://AGV5/meshes/CW_mount_rf.STL</uri>
          </mesh>
        </geometry>
      </collision>
      <collision name='base_link_fixed_joint_lump__CW_mount_rr_collision_4'>
        <pose>0.231388 0.049 0.35 0 -0 0</pose>
        <geometry>
          <mesh>
            <scale>1 1 1</scale>
            <uri>model://AGV5/meshes/CW_mount_rr.STL</uri>
          </mesh>
        </geometry>
      </collision>
      <visual name='base_link_visual'>
        <pose>0 0 0 0 -0 0</pose>
        <geometry>
          <mesh>
            <scale>1 1 1</scale>
            <uri>model://AGV5/meshes/base_link.STL</uri>
          </mesh>
        </geometry>
      </visual>
      <visual name='base_link_fixed_joint_lump__CW_mount_lf_visual_1'>
        <pose>-0.23161 0.049 -0.3574 0 -0 0</pose>
        <geometry>
          <mesh>
            <scale>1 1 1</scale>
            <uri>model://AGV5/meshes/CW_mount_lf.STL</uri>
          </mesh>
        </geometry>
      </visual>
      <visual name='base_link_fixed_joint_lump__CW_mount_lr_visual_2'>
        <pose>-0.23161 0.049 0.35 0 -0 0</pose>
        <geometry>
          <mesh>
            <scale>1 1 1</scale>
            <uri>model://AGV5/meshes/CW_mount_lr.STL</uri>
          </mesh>
        </geometry>
      </visual>
      <visual name='base_link_fixed_joint_lump__CW_mount_rf_visual_3'>
        <pose>0.231387 0.049 -0.3574 0 -0 0</pose>
        <geometry>
          <mesh>
            <scale>1 1 1</scale>
            <uri>model://AGV5/meshes/CW_mount_rf.STL</uri>
          </mesh>
        </geometry>
      </visual>
      <visual name='base_link_fixed_joint_lump__CW_mount_rr_visual_4'>
        <pose>0.231388 0.049 0.35 0 -0 0</pose>
        <geometry>
          <mesh>
            <scale>1 1 1</scale>
            <uri>model://AGV5/meshes/CW_mount_rr.STL</uri>
          </mesh>
        </geometry>
      </visual>
    </link>
    <joint name='CW_brac_lf_joint' type='revolute'>
      <pose relative_to='base_link'>-0.23161 0.049 -0.3574 0 -0 0</pose>
      <parent>base_link</parent>
      <child>CW_brac_lf</child>
      <axis>
        <xyz>0 1 0</xyz>
        <limit>
          <lower>-10</lower>
          <upper>10</upper>
        </limit>
        <dynamics>
          <spring_reference>0</spring_reference>
          <spring_stiffness>0</spring_stiffness>
        </dynamics>
      </axis>
    </joint>
    <link name='CW_brac_lf'>
      <pose relative_to='CW_brac_lf_joint'>0 0 0 0 -0 0</pose>
      <inertial>
        <pose>0 -0.037775 -0.014331 0 -0 0</pose>
        <mass>0.0747206</mass>
        <inertia>
          <ixx>6.84712e-05</ixx>
          <ixy>-3.66816e-11</ixy>
          <ixz>6.36578e-12</ixz>
          <iyy>6.18341e-05</iyy>
          <iyz>-1.41155e-05</iyz>
          <izz>8.2666e-05</izz>
        </inertia>
      </inertial>
      <collision name='CW_brac_lf_collision'>
        <pose>0 0 0 0 -0 0</pose>
        <geometry>
          <mesh>
            <scale>1 1 1</scale>
            <uri>model://AGV5/meshes/CW_brac_lf.STL</uri>
          </mesh>
        </geometry>
      </collision>
      <visual name='CW_brac_lf_visual'>
        <pose>0 0 0 0 -0 0</pose>
        <geometry>
          <mesh>
            <scale>1 1 1</scale>
            <uri>model://AGV5/meshes/CW_brac_lf.STL</uri>
          </mesh>
        </geometry>
      </visual>
    </link>
    <joint name='CW_lf_joint' type='revolute'>
      <pose relative_to='CW_brac_lf'>0 -0.0835 -0.03 0 -0 0</pose>
      <parent>CW_brac_lf</parent>
      <child>CW_lf</child>
      <axis>
        <xyz>1 0 0</xyz>
        <limit>
          <lower>-1e+16</lower>
          <upper>1e+16</upper>
        </limit>
        <dynamics>
          <spring_reference>0</spring_reference>
          <spring_stiffness>0</spring_stiffness>
        </dynamics>
      </axis>
    </joint>
    <link name='CW_lf'>
      <pose relative_to='CW_lf_joint'>0 0 0 0 -0 0</pose>
      <inertial>
        <pose>0 0 0 0 -0 0</pose>
        <mass>0.359205</mass>
        <inertia>
          <ixx>0.000758344</ixx>
          <ixy>-2.28486e-19</ixy>
          <ixz>-6.04252e-18</ixz>
          <iyy>0.000401508</iyy>
          <iyz>-1.40479e-19</iyz>
          <izz>0.000401508</izz>
        </inertia>
      </inertial>
      <collision name='CW_lf_collision'>
        <pose>0 0 0 0 -0 0</pose>
        <geometry>
          <mesh>
            <scale>1 1 1</scale>
            <uri>model://AGV5/meshes/CW_lf.STL</uri>
          </mesh>
        </geometry>
      </collision>
      <visual name='CW_lf_visual'>
        <pose>0 0 0 0 -0 0</pose>
        <geometry>
          <mesh>
            <scale>1 1 1</scale>
            <uri>model://AGV5/meshes/CW_lf.STL</uri>
          </mesh>
        </geometry>
      </visual>
    </link>
    <joint name='CW_brac_lr_joint' type='revolute'>
      <pose relative_to='base_link'>-0.23161 0.049 0.35 0 -0 0</pose>
      <parent>base_link</parent>
      <child>CW_brac_lr</child>
      <axis>
        <xyz>0 1 0</xyz>
        <limit>
          <lower>-1e+16</lower>
          <upper>1e+16</upper>
        </limit>
        <dynamics>
          <spring_reference>0</spring_reference>
          <spring_stiffness>0</spring_stiffness>
        </dynamics>
      </axis>
    </joint>
    <link name='CW_brac_lr'>
      <pose relative_to='CW_brac_lr_joint'>0 0 0 0 -0 0</pose>
      <inertial>
        <pose>-0 -0.037775 0.014331 0 -0 0</pose>
        <mass>0.0747206</mass>
        <inertia>
          <ixx>6.84712e-05</ixx>
          <ixy>3.66816e-11</ixy>
          <ixz>6.36578e-12</ixz>
          <iyy>6.18341e-05</iyy>
          <iyz>1.41155e-05</iyz>
          <izz>8.2666e-05</izz>
        </inertia>
      </inertial>
      <collision name='CW_brac_lr_collision'>
        <pose>0 0 0 0 -0 0</pose>
        <geometry>
          <mesh>
            <scale>1 1 1</scale>
            <uri>model://AGV5/meshes/CW_brac_lr.STL</uri>
          </mesh>
        </geometry>
      </collision>
      <visual name='CW_brac_lr_visual'>
        <pose>0 0 0 0 -0 0</pose>
        <geometry>
          <mesh>
            <scale>1 1 1</scale>
            <uri>model://AGV5/meshes/CW_brac_lr.STL</uri>
          </mesh>
        </geometry>
      </visual>
    </link>
    <joint name='CW_lr_joint' type='revolute'>
      <pose relative_to='CW_brac_lr'>0 -0.0835 0.03 0 -0 0</pose>
      <parent>CW_brac_lr</parent>
      <child>CW_lr</child>
      <axis>
        <xyz>1 0 0</xyz>
        <limit>
          <lower>-1e+16</lower>
          <upper>1e+16</upper>
        </limit>
        <dynamics>
          <spring_reference>0</spring_reference>
          <spring_stiffness>0</spring_stiffness>
        </dynamics>
      </axis>
    </joint>
    <link name='CW_lr'>
      <pose relative_to='CW_lr_joint'>0 0 0 0 -0 0</pose>
      <inertial>
        <pose>0 0 0 0 -0 0</pose>
        <mass>0.359205</mass>
        <inertia>
          <ixx>0.000758344</ixx>
          <ixy>-1.86618e-19</ixy>
          <ixz>-6.01214e-18</ixz>
          <iyy>0.000401508</iyy>
          <iyz>-1.45636e-20</iyz>
          <izz>0.000401508</izz>
        </inertia>
      </inertial>
      <collision name='CW_lr_collision'>
        <pose>0 0 0 0 -0 0</pose>
        <geometry>
          <mesh>
            <scale>1 1 1</scale>
            <uri>model://AGV5/meshes/CW_lr.STL</uri>
          </mesh>
        </geometry>
      </collision>
      <visual name='CW_lr_visual'>
        <pose>0 0 0 0 -0 0</pose>
        <geometry>
          <mesh>
            <scale>1 1 1</scale>
            <uri>model://AGV5/meshes/CW_lr.STL</uri>
          </mesh>
        </geometry>
      </visual>
    </link>
    <joint name='CW_brac_rf_joint' type='revolute'>
      <pose relative_to='base_link'>0.231387 0.049 -0.3574 0 -0 0</pose>
      <parent>base_link</parent>
      <child>CW_brac_rf</child>
      <axis>
        <xyz>0 1 0</xyz>
        <limit>
          <lower>-1e+16</lower>
          <upper>1e+16</upper>
        </limit>
        <dynamics>
          <spring_reference>0</spring_reference>
          <spring_stiffness>0</spring_stiffness>
        </dynamics>
      </axis>
    </joint>
    <link name='CW_brac_rf'>
      <pose relative_to='CW_brac_rf_joint'>0 0 0 0 -0 0</pose>
      <inertial>
        <pose>0 -0.037775 -0.014331 0 -0 0</pose>
        <mass>0.0747206</mass>
        <inertia>
          <ixx>6.84712e-05</ixx>
          <ixy>-3.66816e-11</ixy>
          <ixz>6.36578e-12</ixz>
          <iyy>6.18341e-05</iyy>
          <iyz>-1.41155e-05</iyz>
          <izz>8.2666e-05</izz>
        </inertia>
      </inertial>
      <collision name='CW_brac_rf_collision'>
        <pose>0 0 0 0 -0 0</pose>
        <geometry>
          <mesh>
            <scale>1 1 1</scale>
            <uri>model://AGV5/meshes/CW_brac_rf.STL</uri>
          </mesh>
        </geometry>
      </collision>
      <visual name='CW_brac_rf_visual'>
        <pose>0 0 0 0 -0 0</pose>
        <geometry>
          <mesh>
            <scale>1 1 1</scale>
            <uri>model://AGV5/meshes/CW_brac_rf.STL</uri>
          </mesh>
        </geometry>
      </visual>
    </link>
    <joint name='CW_rf_joint' type='revolute'>
      <pose relative_to='CW_brac_rf'>0 -0.0835 -0.03 0 -0 0</pose>
      <parent>CW_brac_rf</parent>
      <child>CW_rf</child>
      <axis>
        <xyz>1 0 0</xyz>
        <limit>
          <lower>-1e+16</lower>
          <upper>1e+16</upper>
        </limit>
        <dynamics>
          <spring_reference>0</spring_reference>
          <spring_stiffness>0</spring_stiffness>
        </dynamics>
      </axis>
    </joint>
    <link name='CW_rf'>
      <pose relative_to='CW_rf_joint'>0 0 0 0 -0 0</pose>
      <inertial>
        <pose>0 0 0 0 -0 0</pose>
        <mass>0.359205</mass>
        <inertia>
          <ixx>0.000758344</ixx>
          <ixy>-2.36066e-19</ixy>
          <ixz>-6.09234e-18</ixz>
          <iyy>0.000401508</iyy>
          <iyz>1.31258e-20</iyz>
          <izz>0.000401508</izz>
        </inertia>
      </inertial>
      <collision name='CW_rf_collision'>
        <pose>0 0 0 0 -0 0</pose>
        <geometry>
          <mesh>
            <scale>1 1 1</scale>
            <uri>model://AGV5/meshes/CW_rf.STL</uri>
          </mesh>
        </geometry>
      </collision>
      <visual name='CW_rf_visual'>
        <pose>0 0 0 0 -0 0</pose>
        <geometry>
          <mesh>
            <scale>1 1 1</scale>
            <uri>model://AGV5/meshes/CW_rf.STL</uri>
          </mesh>
        </geometry>
      </visual>
    </link>
    <joint name='CW_brac_rr_joint' type='revolute'>
      <pose relative_to='base_link'>0.231388 0.049 0.35 0 -0 0</pose>
      <parent>base_link</parent>
      <child>CW_brac_rr</child>
      <axis>
        <xyz>0 1 0</xyz>
        <limit>
          <lower>-1e+16</lower>
          <upper>1e+16</upper>
        </limit>
        <dynamics>
          <spring_reference>0</spring_reference>
          <spring_stiffness>0</spring_stiffness>
        </dynamics>
      </axis>
    </joint>
    <link name='CW_brac_rr'>
      <pose relative_to='CW_brac_rr_joint'>0 0 0 0 -0 0</pose>
      <inertial>
        <pose>-0 -0.037775 0.014331 0 -0 0</pose>
        <mass>0.0747206</mass>
        <inertia>
          <ixx>6.84712e-05</ixx>
          <ixy>3.66816e-11</ixy>
          <ixz>6.36578e-12</ixz>
          <iyy>6.18341e-05</iyy>
          <iyz>1.41155e-05</iyz>
          <izz>8.2666e-05</izz>
        </inertia>
      </inertial>
      <collision name='CW_brac_rr_collision'>
        <pose>0 0 0 0 -0 0</pose>
        <geometry>
          <mesh>
            <scale>1 1 1</scale>
            <uri>model://AGV5/meshes/CW_brac_rr.STL</uri>
          </mesh>
        </geometry>
      </collision>
      <visual name='CW_brac_rr_visual'>
        <pose>0 0 0 0 -0 0</pose>
        <geometry>
          <mesh>
            <scale>1 1 1</scale>
            <uri>model://AGV5/meshes/CW_brac_rr.STL</uri>
          </mesh>
        </geometry>
      </visual>
    </link>
    <joint name='CW_rr_joint' type='revolute'>
      <pose relative_to='CW_brac_rr'>0 -0.0835 0.03 0 -0 0</pose>
      <parent>CW_brac_rr</parent>
      <child>CW_rr</child>
      <axis>
        <xyz>1 0 0</xyz>
        <limit>
          <lower>-1e+16</lower>
          <upper>1e+16</upper>
        </limit>
        <dynamics>
          <spring_reference>0</spring_reference>
          <spring_stiffness>0</spring_stiffness>
        </dynamics>
      </axis>
    </joint>
    <link name='CW_rr'>
      <pose relative_to='CW_rr_joint'>0 0 0 0 -0 0</pose>
      <inertial>
        <pose>0 0 0 0 -0 0</pose>
        <mass>0.359205</mass>
        <inertia>
          <ixx>0.000758344</ixx>
          <ixy>3.37551e-37</ixy>
          <ixz>-1.61616e-20</ixz>
          <iyy>0.000401508</iyy>
          <iyz>-2.24637e-20</iyz>
          <izz>0.000401508</izz>
        </inertia>
      </inertial>
      <collision name='CW_rr_collision'>
        <pose>0 0 0 0 -0 0</pose>
        <geometry>
          <mesh>
            <scale>1 1 1</scale>
            <uri>model://AGV5/meshes/CW_rr.STL</uri>
          </mesh>
        </geometry>
      </collision>
      <visual name='CW_rr_visual'>
        <pose>0 0 0 0 -0 0</pose>
        <geometry>
          <mesh>
            <scale>1 1 1</scale>
            <uri>model://AGV5/meshes/CW_rr.STL</uri>
          </mesh>
        </geometry>
      </visual>
    </link>
    <joint name='DW_L_joint' type='revolute'>
      <pose relative_to='base_link'>-0.2315 0 0 0 -0 0</pose>
      <parent>base_link</parent>
      <child>DW_L</child>
      <axis>
        <xyz>-1 0 0</xyz>
        <limit>
          <lower>-1e+16</lower>
          <upper>1e+16</upper>
        </limit>
        <dynamics>
          <spring_reference>0</spring_reference>
          <spring_stiffness>0</spring_stiffness>
        </dynamics>
      </axis>
    </joint>
    <link name='DW_L'>
      <pose relative_to='DW_L_joint'>0 0 0 0 -0 0</pose>
      <inertial>
        <pose>-0 0 0 0 -0 0</pose>
        <mass>21.1289</mass>
        <inertia>
          <ixx>0.0951176</ixx>
          <ixy>1.19813e-18</ixy>
          <ixz>5.01207e-20</ixz>
          <iyy>0.0624868</iyy>
          <iyz>-4.36538e-08</iyz>
          <izz>0.0624865</izz>
        </inertia>
      </inertial>
      <collision name='DW_L_collision'>
        <pose>0 0 0 0 -0 0</pose>
        <geometry>
          <mesh>
            <scale>1 1 1</scale>
            <uri>model://AGV5/meshes/DW_L.STL</uri>
          </mesh>
        </geometry>
      </collision>
      <visual name='DW_L_visual'>
        <pose>0 0 0 0 -0 0</pose>
        <geometry>
          <mesh>
            <scale>1 1 1</scale>
            <uri>model://AGV5/meshes/DW_L.STL</uri>
          </mesh>
        </geometry>
      </visual>
    </link>
    <joint name='DW_R_joint' type='revolute'>
      <pose relative_to='base_link'>0.2315 0 0 0 -0 0</pose>
      <parent>base_link</parent>
      <child>DW_R</child>
      <axis>
        <xyz>-1 0 0</xyz>
        <limit>
          <lower>-1e+16</lower>
          <upper>1e+16</upper>
        </limit>
        <dynamics>
          <spring_reference>0</spring_reference>
          <spring_stiffness>0</spring_stiffness>
        </dynamics>
      </axis>
    </joint>
    <link name='DW_R'>
      <pose relative_to='DW_R_joint'>0 0 0 0 -0 0</pose>
      <inertial>
        <pose>0 -0 0 0 -0 0</pose>
        <mass>21.1289</mass>
        <inertia>
          <ixx>0.0951176</ixx>
          <ixy>1.21264e-18</ixy>
          <ixz>4.24098e-20</ixz>
          <iyy>0.0624868</iyy>
          <iyz>-3.44651e-08</iyz>
          <izz>0.0624865</izz>
        </inertia>
      </inertial>
      <collision name='DW_R_collision'>
        <pose>0 0 0 0 -0 0</pose>
        <geometry>
          <mesh>
            <scale>1 1 1</scale>
            <uri>model://AGV5/meshes/DW_R.STL</uri>
          </mesh>
        </geometry>
      </collision>
      <visual name='DW_R_visual'>
        <pose>0 0 0 0 -0 0</pose>
        <geometry>
          <mesh>
            <scale>1 1 1</scale>
            <uri>model://AGV5/meshes/DW_R.STL</uri>
          </mesh>
        </geometry>
      </visual>
    </link>
    <joint name='bot_slider_l_joint' type='prismatic'>
      <pose relative_to='base_link'>-0.23161 0.178 -0.31051 0 -0 0</pose>
      <parent>base_link</parent>
      <child>bot_slider_l</child>
      <axis>
        <xyz>0 0 1</xyz>
        <limit>
          <lower>-0.077</lower>
          <upper>0.081</upper>
          
          
        </limit>
        <dynamics>
          <spring_reference>0</spring_reference>
          <spring_stiffness>0</spring_stiffness>
        </dynamics>
      </axis>
    </joint>
    <link name='bot_slider_l'>
      <pose relative_to='bot_slider_l_joint'>0 0 0 0 -0 0</pose>
      <inertial>
        <pose>3e-05 -0.020019 -0.00787 0 -0 0</pose>
        <mass>0.114142</mass>
        <inertia>
          <ixx>0.000170721</ixx>
          <ixy>1.76119e-10</ixy>
          <ixz>-1.84223e-10</ixz>
          <iyy>0.000166924</iyy>
          <iyz>-3.89845e-05</iyz>
          <izz>0.000103621</izz>
        </inertia>
      </inertial>
      <collision name='bot_slider_l_collision'>
        <pose>0 0 0 0 -0 0</pose>
        <geometry>
          <mesh>
            <scale>1 1 1</scale>
            <uri>model://AGV5/meshes/bot_slider_l.STL</uri>
          </mesh>
        </geometry>
      </collision>
      <visual name='bot_slider_l_visual'>
        <pose>0 0 0 0 -0 0</pose>
        <geometry>
          <mesh>
            <scale>1 1 1</scale>
            <uri>model://AGV5/meshes/bot_slider_l.STL</uri>
          </mesh>
        </geometry>
      </visual>
    </link>
    <joint name='sci_l_A_joint' type='revolute'>
      <pose relative_to='bot_slider_l'>0 0 0 0 -0 0</pose>
      <parent>bot_slider_l</parent>
      <child>sci_l_A</child>
      <axis>
        <xyz>1 0 0</xyz>
        <limit>
          <lower>-10</lower>
          <upper>10</upper>
        </limit>
        <dynamics>
          <spring_reference>0</spring_reference>
          <spring_stiffness>0</spring_stiffness>
        </dynamics>
      </axis>
    </joint>
    <link name='sci_l_A'>
      <pose relative_to='sci_l_A_joint'>0 0 0 0 -0 0</pose>
      <inertial>
        <pose>-0.003208 0.196826 0.344231 0 -0 0</pose>
        <mass>0.674706</mass>
        <inertia>
          <ixx>0.0033198</ixx>
          <ixy>-2.88817e-09</ixy>
          <ixz>2.73771e-09</ixz>
          <iyy>0.00255037</iyy>
          <iyz>-0.00132711</iyz>
          <izz>0.00108606</izz>
        </inertia>
      </inertial>
      <collision name='sci_l_A_collision'>
        <pose>0 0 0 0 -0 0</pose>
        <geometry>
          <mesh>
            <scale>1 1 1</scale>
            <uri>model://AGV5/meshes/sci_l_A.STL</uri>
          </mesh>
        </geometry>
      </collision>
      <visual name='sci_l_A_visual'>
        <pose>0 0 0 0 -0 0</pose>
        <geometry>
          <mesh>
            <scale>1 1 1</scale>
            <uri>model://AGV5/meshes/sci_l_A.STL</uri>
          </mesh>
        </geometry>
      </visual>
    </link>
    <joint name='sci_bot_l_joint' type='revolute'>
      <pose relative_to='sci_l_A'>0 0.19607 0.3429 0 -0 0</pose>
      <parent>sci_l_A</parent>
      <child>sci_bot_l</child>
      <axis>
        <xyz>1 0 0</xyz>
        <limit>
          <lower>-10</lower>
          <upper>10</upper>
        </limit>
        <dynamics>
          <spring_reference>0</spring_reference>
          <spring_stiffness>0</spring_stiffness>
        </dynamics>
      </axis>
    </joint>
    <link name='sci_bot_l'>
      <pose relative_to='sci_bot_l_joint'>0 0 0 0 -0 0</pose>
      <inertial>
        <pose>0 0 0 0 -0 0</pose>
        <mass>1.0709</mass>
        <inertia>
          <ixx>0.000255204</ixx>
          <ixy>2.8516e-21</ixy>
          <ixz>-1.27151e-17</ixz>
          <iyy>0.000855782</iyy>
          <iyz>-1.97748e-20</iyz>
          <izz>0.000855782</izz>
        </inertia>
      </inertial>
      <collision name='sci_bot_l_collision'>
        <pose>0 0 0 0 -0 0</pose>
        <geometry>
          <mesh>
            <scale>1 1 1</scale>
            <uri>model://AGV5/meshes/sci_bot_l.STL</uri>
          </mesh>
        </geometry>
      </collision>
      <visual name='sci_bot_l_visual'>
        <pose>0 0 0 0 -0 0</pose>
        <geometry>
          <mesh>
            <scale>1 1 1</scale>
            <uri>model://AGV5/meshes/sci_bot_l.STL</uri>
          </mesh>
        </geometry>
      </visual>
    </link>
    <joint name='sci_l_B_joint' type='revolute'>
      <pose relative_to='sci_bot_l'>0 0 0 0 -0 0</pose>
      <parent>sci_bot_l</parent>
      <child>sci_l_B</child>
      <axis>
        <xyz>1 0 0</xyz>
        <limit>
          <lower>-10</lower>
          <upper>10</upper>
        </limit>
        <dynamics>
          <spring_reference>0</spring_reference>
          <spring_stiffness>0</spring_stiffness>
        </dynamics>
      </axis>
    </joint>
    <link name='sci_l_B'>
      <pose relative_to='sci_l_B_joint'>0 0 0 0 -0 0</pose>
      <inertial>
        <pose>0.003208 0.000758 -0.001329 0 -0 0</pose>
        <mass>0.674706</mass>
        <inertia>
          <ixx>0.0033198</ixx>
          <ixy>2.88817e-09</ixy>
          <ixz>2.73771e-09</ixz>
          <iyy>0.00255037</iyy>
          <iyz>0.00132711</iyz>
          <izz>0.00108606</izz>
        </inertia>
      </inertial>
      <collision name='sci_l_B_collision'>
        <pose>0 0 0 0 -0 0</pose>
        <geometry>
          <mesh>
            <scale>1 1 1</scale>
            <uri>model://AGV5/meshes/sci_l_B.STL</uri>
          </mesh>
        </geometry>
      </collision>
      <visual name='sci_l_B_visual'>
        <pose>0 0 0 0 -0 0</pose>
        <geometry>
          <mesh>
            <scale>1 1 1</scale>
            <uri>model://AGV5/meshes/sci_l_B.STL</uri>
          </mesh>
        </geometry>
      </visual>
    </link>
    <joint name='virtual_base_l_joint' type='revolute'>
      <pose relative_to='sci_l_B'>0 -0.19607 0.3429 0 -0 0</pose>
      <parent>sci_l_B</parent>
      <child>base_link</child>
      <axis>
        <xyz>1 0 0</xyz>
        <limit>
          <lower>-10</lower>
          <upper>10</upper>
        </limit>
        <dynamics>
          <spring_reference>0</spring_reference>
          <spring_stiffness>0</spring_stiffness>
        </dynamics>
      </axis>
    </joint>

    <joint name='top_fixed_l_A_joint' type='revolute'>
      <pose relative_to='sci_l_A'>0 0.39214 0.68581 0 -0 0</pose>
      <parent>sci_l_A</parent>
      <child>top_fixed_l_A</child>
      <axis>
        <xyz>1 0 0</xyz>
        <limit>
          <lower>-10</lower>
          <upper>10</upper>
        </limit>
        <dynamics>
          <spring_reference>0</spring_reference>
          <spring_stiffness>0</spring_stiffness>
        </dynamics>
      </axis>
    </joint>
    <link name='top_fixed_l_A'>
      <pose relative_to='top_fixed_l_A_joint'>0 0 0 0 -0 0</pose>
      <inertial>
        <pose>0 0.029268 -0 0 -0 0</pose>
        <mass>0.175465</mass>
        <inertia>
          <ixx>0.000145637</ixx>
          <ixy>-1.17278e-10</ixy>
          <ixz>-3.1452e-11</ixz>
          <iyy>0.0001172</iyy>
          <iyz>3.32238e-11</iyz>
          <izz>0.000198824</izz>
        </inertia>
      </inertial>
      <collision name='top_fixed_l_A_collision'>
        <pose>0 0 0 0 -0 0</pose>
        <geometry>
          <mesh>
            <scale>1 1 1</scale>
            <uri>model://AGV5/meshes/top_fixed_l_A.STL</uri>
          </mesh>
        </geometry>
      </collision>
      <visual name='top_fixed_l_A_visual'>
        <pose>0 0 0 0 -0 0</pose>
        <geometry>
          <mesh>
            <scale>1 1 1</scale>
            <uri>model://AGV5/meshes/top_fixed_l_A.STL</uri>
          </mesh>
        </geometry>
      </visual>
    </link>
    <joint name='top_fixed_l_B_joint' type='revolute'>
      <pose relative_to='top_fixed_l_A'>0 0.07 0 0 -0 0</pose>
      <parent>top_fixed_l_A</parent>
      <child>top_fixed_l_B</child>
      <axis>
        <xyz>0 0 -1</xyz>
        <limit>
          <lower>-10</lower>
          <upper>10</upper>
        </limit>
        <dynamics>
          <spring_reference>0</spring_reference>
          <spring_stiffness>0</spring_stiffness>
        </dynamics>
      </axis>
    </joint>
    <link name='top_fixed_l_B'>
      <pose relative_to='top_fixed_l_B_joint'>0 0 0 0 -0 0</pose>
      <inertial>
        <pose>0 0.029268 0 0 -0 0</pose>
        <mass>0.175465</mass>
        <inertia>
          <ixx>0.000198824</ixx>
          <ixy>-3.32239e-11</ixy>
          <ixz>3.1452e-11</ixz>
          <iyy>0.0001172</iyy>
          <iyz>-1.17278e-10</iyz>
          <izz>0.000145637</izz>
        </inertia>
      </inertial>
      <collision name='top_fixed_l_B_collision'>
        <pose>0 0 0 0 -0 0</pose>
        <geometry>
          <mesh>
            <scale>1 1 1</scale>
            <uri>model://AGV5/meshes/top_fixed_l_B.STL</uri>
          </mesh>
        </geometry>
      </collision>
      <visual name='top_fixed_l_B_visual'>
        <pose>0 0 0 0 -0 0</pose>
        <geometry>
          <mesh>
            <scale>1 1 1</scale>
            <uri>model://AGV5/meshes/top_fixed_l_B.STL</uri>
          </mesh>
        </geometry>
      </visual>
    </link>
    <joint name='TM_base_joint' type='revolute'>
      <pose relative_to='top_fixed_l_B'>0 0.07 0 0 -0 0</pose>
      <parent>top_fixed_l_B</parent>
      <child>TM_base</child>
      <axis>
        <xyz>0 0 -1</xyz>
        <limit>
          <lower>-10</lower>
          <upper>10</upper>
        </limit>
        <dynamics>
          <spring_reference>0</spring_reference>
          <spring_stiffness>0</spring_stiffness>
        </dynamics>
      </axis>
    </joint>
    <link name='TM_base'>
      <pose relative_to='TM_base_joint'>0 0 0 0 -0 0</pose>
      <inertial>
        <pose>0.291868 0.017569 -0.370862 0 -0 0</pose>
        <mass>8.41981</mass>
        <inertia>
          <ixx>0.523004</ixx>
          <ixy>1.43308e-06</ixy>
          <ixz>-7.44856e-07</ixz>
          <iyy>0.791445</iyy>
          <iyz>3.47329e-07</iyz>
          <izz>0.282393</izz>
        </inertia>
      </inertial>
      <collision name='TM_base_collision'>
        <pose>0 0 0 0 -0 0</pose>
        <geometry>
          <mesh>
            <scale>1 1 1</scale>
            <uri>model://AGV5/meshes/TM_base.STL</uri>
          </mesh>
        </geometry>
      </collision>
      <visual name='TM_base_visual'>
        <pose>0 0 0 0 -0 0</pose>
        <geometry>
          <mesh>
            <scale>1 1 1</scale>
            <uri>model://AGV5/meshes/TM_base.STL</uri>
          </mesh>
        </geometry>
      </visual>
    </link>
    <joint name='TM_slider_joint' type='prismatic'>
      <pose relative_to='TM_base'>0.427639 -0.011195 0.177499 0 -0 0</pose>
      <parent>TM_base</parent>
      <child>TM_slider</child>
      <axis>
        <xyz>-1 0 0</xyz>
        <limit>
          <lower>0</lower>
          <upper>0.4</upper>
          
          
        </limit>
        <dynamics>
          <spring_reference>0</spring_reference>
          <spring_stiffness>0</spring_stiffness>
        </dynamics>
      </axis>
    </joint>
    <link name='TM_slider'>
      <pose relative_to='TM_slider_joint'>0 0 0 0 -0 0</pose>
      <inertial>
        <pose>0.000173 0.019908 -0.5525 0 -0 0</pose>
        <mass>0.646006</mass>
        <inertia>
          <ixx>0.000659085</ixx>
          <ixy>1.12463e-13</ixy>
          <ixz>-2.50868e-08</ixz>
          <iyy>0.00167105</iyy>
          <iyz>2.25523e-13</iyz>
          <izz>0.00169044</izz>
        </inertia>
      </inertial>
      <collision name='TM_slider_collision'>
        <pose>0 0 0 0 -0 0</pose>
        <geometry>
          <mesh>
            <scale>1 1 1</scale>
            <uri>model://AGV5/meshes/TM_slider.STL</uri>
          </mesh>
        </geometry>
      </collision>
      <visual name='TM_slider_visual'>
        <pose>0 0 0 0 -0 0</pose>
        <geometry>
          <mesh>
            <scale>1 1 1</scale>
            <uri>model://AGV5/meshes/TM_slider.STL</uri>
          </mesh>
        </geometry>
      </visual>
    </link>
    <joint name='TM_loader_joint' type='revolute'>
      <pose relative_to='TM_slider'>0.045 -0.021805 0.08225 0 -0 0</pose>
      <parent>TM_slider</parent>
      <child>TM_loader</child>
      <axis>
        <xyz>0 0 -1</xyz>
        <limit>
          <lower>-1.5</lower>
          <upper>1</upper>
        </limit>
        <dynamics>
          <spring_reference>0</spring_reference>
          <spring_stiffness>0</spring_stiffness>
        </dynamics>
      </axis>
    </joint>
    <link name='TM_loader'>
      <pose relative_to='TM_loader_joint'>0 0 0 0 -0 0</pose>
      <inertial>
        <pose>0.101113 0.142464 -0.634749 0 -0 0</pose>
        <mass>0.166984</mass>
        <inertia>
          <ixx>0.010419</ixx>
          <ixy>-0.000240777</ixy>
          <ixz>2.95805e-16</ixz>
          <iyy>0.0102507</iyy>
          <iyz>9.37534e-17</iyz>
          <izz>0.000530782</izz>
        </inertia>
      </inertial>
      <collision name='TM_loader_collision'>
        <pose>0 0 0 0 -0 0</pose>
        <geometry>
          <mesh>
            <scale>1 1 1</scale>
            <uri>model://AGV5/meshes/TM_loader.STL</uri>
          </mesh>
        </geometry>
      </collision>
      <visual name='TM_loader_visual'>
        <pose>0 0 0 0 -0 0</pose>
        <geometry>
          <mesh>
            <scale>1 1 1</scale>
            <uri>model://AGV5/meshes/TM_loader.STL</uri>
          </mesh>
        </geometry>
      </visual>
    </link>
    <joint name='top_fixed_mount_r_joint' type='revolute'>
      <pose relative_to='TM_base'>0.463 0 0 0 -0 0</pose>
      <parent>TM_base</parent>
      <child>top_fixed_mount_r</child>
      <axis>
        <xyz>0 0 -1</xyz>
        <limit>
          <lower>-10</lower>
          <upper>10</upper>
        </limit>
        <dynamics>
          <spring_reference>0</spring_reference>
          <spring_stiffness>0</spring_stiffness>
        </dynamics>
      </axis>
    </joint>
    <link name='top_fixed_mount_r'>
      <pose relative_to='top_fixed_mount_r_joint'>0 0 0 0 -0 0</pose>
      <inertial>
        <pose>0 -0.040732 -0 0 -0 0</pose>
        <mass>0.175465</mass>
        <inertia>
          <ixx>0.000145637</ixx>
          <ixy>-1.17278e-10</ixy>
          <ixz>-3.1452e-11</ixz>
          <iyy>0.0001172</iyy>
          <iyz>3.32238e-11</iyz>
          <izz>0.000198824</izz>
        </inertia>
      </inertial>
      <collision name='top_fixed_mount_r_collision'>
        <pose>0 0 0 0 -0 0</pose>
        <geometry>
          <mesh>
            <scale>1 1 1</scale>
            <uri>model://AGV5/meshes/top_fixed_mount_r.STL</uri>
          </mesh>
        </geometry>
      </collision>
      <visual name='top_fixed_mount_r_visual'>
        <pose>0 0 0 0 -0 0</pose>
        <geometry>
          <mesh>
            <scale>1 1 1</scale>
            <uri>model://AGV5/meshes/top_fixed_mount_r.STL</uri>
          </mesh>
        </geometry>
      </visual>
    </link>
    <joint name='virtual_sci_r_2_joint' type='revolute'>
      <pose relative_to='top_fixed_mount_r'>0 -0.07 0 0 -0 0</pose>
      <parent>top_fixed_mount_r</parent>
      <child>sci_r_A</child>
      <axis>
        <xyz>-1 0 0</xyz>
        <limit>
          <lower>-10</lower>
          <upper>10</upper>
        </limit>
        <dynamics>
          <spring_reference>0</spring_reference>
          <spring_stiffness>0</spring_stiffness>
        </dynamics>
      </axis>
    </joint>

    <joint name='top_slider_l_joint' type='revolute'>
      <pose relative_to='TM_base'>0 0 -0.578 0 -0 0</pose>
      <parent>TM_base</parent>
      <child>top_slider_l</child>
      <axis>
        <xyz>0 0 1</xyz>
        <limit>
          <lower>-10</lower>
          <upper>10</upper>
        </limit>
        <dynamics>
          <spring_reference>0</spring_reference>
          <spring_stiffness>0</spring_stiffness>
        </dynamics>
      </axis>
    </joint>
    <link name='top_slider_l'>
      <pose relative_to='top_slider_l_joint'>0 0 0 0 -0 0</pose>
      <inertial>
        <pose>-0 0 0 0 -0 0</pose>
        <mass>0.53464</mass>
        <inertia>
          <ixx>0.0126331</ixx>
          <ixy>6.30109e-21</ixy>
          <ixz>-3.84977e-18</ixz>
          <iyy>0.0126331</iyy>
          <iyz>5.31885e-19</iyz>
          <izz>4.24138e-05</izz>
        </inertia>
      </inertial>
      <collision name='top_slider_l_collision'>
        <pose>0 0 0 0 -0 0</pose>
        <geometry>
          <mesh>
            <scale>1 1 1</scale>
            <uri>model://AGV5/meshes/top_slider_l.STL</uri>
          </mesh>
        </geometry>
      </collision>
      <visual name='top_slider_l_visual'>
        <pose>0 0 0 0 -0 0</pose>
        <geometry>
          <mesh>
            <scale>1 1 1</scale>
            <uri>model://AGV5/meshes/top_slider_l.STL</uri>
          </mesh>
        </geometry>
      </visual>
    </link>
    <joint name='top_slider_l_B_joint' type='prismatic'>
      <pose relative_to='top_slider_l'>0 0 -0.10781 0 -0 0</pose>
      <parent>top_slider_l</parent>
      <child>top_slider_l_B</child>
      <axis>
        <xyz>0 0 1</xyz>
        <limit>
          <lower>-0.1</lower>
          <upper>0.1</upper>
          
          
        </limit>
        <dynamics>
          <spring_reference>0</spring_reference>
          <spring_stiffness>0</spring_stiffness>
        </dynamics>
      </axis>
    </joint>
    <link name='top_slider_l_B'>
      <pose relative_to='top_slider_l_B_joint'>0 0 0 0 -0 0</pose>
      <inertial>
        <pose>-0 -0.033336 -0 0 -0 0</pose>
        <mass>0.272838</mass>
        <inertia>
          <ixx>0.000197253</ixx>
          <ixy>2.78034e-18</ixy>
          <ixz>-4.02851e-14</ixz>
          <iyy>0.000224314</iyy>
          <iyz>1.01203e-19</iyz>
          <izz>0.000136574</izz>
        </inertia>
      </inertial>
      <collision name='top_slider_l_B_collision'>
        <pose>0 0 0 0 -0 0</pose>
        <geometry>
          <mesh>
            <scale>1 1 1</scale>
            <uri>model://AGV5/meshes/top_slider_l_B.STL</uri>
          </mesh>
        </geometry>
      </collision>
      <visual name='top_slider_l_B_visual'>
        <pose>0 0 0 0 -0 0</pose>
        <geometry>
          <mesh>
            <scale>1 1 1</scale>
            <uri>model://AGV5/meshes/top_slider_l_B.STL</uri>
          </mesh>
        </geometry>
      </visual>
    </link>
    <joint name='top_slider_l_A_joint' type='revolute'>
      <pose relative_to='top_slider_l_B'>0 -0.07 0 0 -0 0</pose>
      <parent>top_slider_l_B</parent>
      <child>top_slider_l_A</child>
      <axis>
        <xyz>0 0 -1</xyz>
        <limit>
          <lower>-10</lower>
          <upper>10</upper>
        </limit>
        <dynamics>
          <spring_reference>0</spring_reference>
          <spring_stiffness>0</spring_stiffness>
        </dynamics>
      </axis>
    </joint>
    <link name='top_slider_l_A'>
      <pose relative_to='top_slider_l_A_joint'>0 0 0 0 -0 0</pose>
      <inertial>
        <pose>0 -0.040732 -0 0 -0 0</pose>
        <mass>0.175465</mass>
        <inertia>
          <ixx>0.000145637</ixx>
          <ixy>-1.17278e-10</ixy>
          <ixz>-3.1452e-11</ixz>
          <iyy>0.0001172</iyy>
          <iyz>3.32238e-11</iyz>
          <izz>0.000198824</izz>
        </inertia>
      </inertial>
      <collision name='top_slider_l_A_collision'>
        <pose>0 0 0 0 -0 0</pose>
        <geometry>
          <mesh>
            <scale>1 1 1</scale>
            <uri>model://AGV5/meshes/top_slider_l_A.STL</uri>
          </mesh>
        </geometry>
      </collision>
      <visual name='top_slider_l_A_visual'>
        <pose>0 0 0 0 -0 0</pose>
        <geometry>
          <mesh>
            <scale>1 1 1</scale>
            <uri>model://AGV5/meshes/top_slider_l_A.STL</uri>
          </mesh>
        </geometry>
      </visual>
    </link>
    <joint name='virtual_sci_l_1_joint' type='revolute'>
      <pose relative_to='top_slider_l_A'>0 -0.07 0 0 -0 0</pose>
      <parent>top_slider_l_A</parent>
      <child>sci_l_B</child>
      <axis>
        <xyz>1 0 0</xyz>
        <limit>
          <lower>-10</lower>
          <upper>10</upper>
        </limit>
        <dynamics>
          <spring_reference>0</spring_reference>
          <spring_stiffness>0</spring_stiffness>
        </dynamics>
      </axis>
    </joint>
  
    <joint name='top_slider_r_joint' type='revolute'>
      <pose relative_to='TM_base'>0.463 0 -0.528 0 -0 0</pose>
      <parent>TM_base</parent>
      <child>top_slider_r</child>
      <axis>
        <xyz>0 0 1</xyz>
        <limit>
          <lower>-10</lower>
          <upper>10</upper>
        </limit>
        <dynamics>
          <spring_reference>0</spring_reference>
          <spring_stiffness>0</spring_stiffness>
        </dynamics>
      </axis>
    </joint>
    <link name='top_slider_r'>
      <pose relative_to='top_slider_r_joint'>0 0 0 0 -0 0</pose>
      <inertial>
        <pose>0 0 0 0 -0 0</pose>
        <mass>0.53464</mass>
        <inertia>
          <ixx>0.0126331</ixx>
          <ixy>-4.34263e-22</ixy>
          <ixz>1.303e-17</ixz>
          <iyy>0.0126331</iyy>
          <iyz>4.77829e-18</iyz>
          <izz>4.24138e-05</izz>
        </inertia>
      </inertial>
      <collision name='top_slider_r_collision'>
        <pose>0 0 0 0 -0 0</pose>
        <geometry>
          <mesh>
            <scale>1 1 1</scale>
            <uri>model://AGV5/meshes/top_slider_r.STL</uri>
          </mesh>
        </geometry>
      </collision>
      <visual name='top_slider_r_visual'>
        <pose>0 0 0 0 -0 0</pose>
        <geometry>
          <mesh>
            <scale>1 1 1</scale>
            <uri>model://AGV5/meshes/top_slider_r.STL</uri>
          </mesh>
        </geometry>
      </visual>
    </link>
    <joint name='top_slider_mount_r_joint' type='prismatic'>
      <pose relative_to='top_slider_r'>0 0 -0.112727 0 -0 0</pose>
      <parent>top_slider_r</parent>
      <child>top_slider_mount_r</child>
      <axis>
        <xyz>0 0 1</xyz>
        <limit>
          <lower>-0.12</lower>
          <upper>0.064</upper>
          
          
        </limit>
        <dynamics>
          <spring_reference>0</spring_reference>
          <spring_stiffness>0</spring_stiffness>
        </dynamics>
      </axis>
    </joint>
    <link name='top_slider_mount_r'>
      <pose relative_to='top_slider_mount_r_joint'>0 0 0 0 -0 0</pose>
      <inertial>
        <pose>-0 -0.033336 0 0 -0 0</pose>
        <mass>0.272838</mass>
        <inertia>
          <ixx>0.000131331</ixx>
          <ixy>3.40936e-15</ixy>
          <ixz>-4.30217e-15</ixz>
          <iyy>0.000224314</iyy>
          <iyz>-1.2039e-15</iyz>
          <izz>0.000202495</izz>
        </inertia>
      </inertial>
      <collision name='top_slider_mount_r_collision'>
        <pose>0 0 0 0 -0 0</pose>
        <geometry>
          <mesh>
            <scale>1 1 1</scale>
            <uri>model://AGV5/meshes/top_slider_mount_r.STL</uri>
          </mesh>
        </geometry>
      </collision>
      <visual name='top_slider_mount_r_visual'>
        <pose>0 0 0 0 -0 0</pose>
        <geometry>
          <mesh>
            <scale>1 1 1</scale>
            <uri>model://AGV5/meshes/top_slider_mount_r.STL</uri>
          </mesh>
        </geometry>
      </visual>
    </link>
    <joint name='virtual_sci_r_1_joint' type='revolute'>
      <pose relative_to='top_slider_mount_r'>0 -0.07 0 0 -0 0</pose>
      <parent>top_slider_mount_r</parent>
      <child>sci_r_B</child>
      <axis>
        <xyz>-1 0 0</xyz>
        <limit>
          <lower>-10</lower>
          <upper>10</upper>
        </limit>
        <dynamics>
          <spring_reference>0</spring_reference>
          <spring_stiffness>0</spring_stiffness>
        </dynamics>
      </axis>
    </joint>
    
    <joint name='bot_slider_r_joint' type='prismatic'>
      <pose relative_to='base_link'>0.231387 0.178 -0.265427 0 -0 0</pose>
      <parent>base_link</parent>
      <child>bot_slider_r</child>
      <axis>
        <xyz>0 0 -1</xyz>
        <limit>
          <lower>-0.1</lower>
          <upper>0.1</upper>
          
          
        </limit>
        <dynamics>
          <spring_reference>0</spring_reference>
          <spring_stiffness>0</spring_stiffness>
        </dynamics>
      </axis>
    </joint>
    <link name='bot_slider_r'>
      <pose relative_to='bot_slider_r_joint'>0 0 0 0 -0 0</pose>
      <inertial>
        <pose>3e-05 -0.020019 -0.00787 0 -0 0</pose>
        <mass>0.114142</mass>
        <inertia>
          <ixx>0.000170721</ixx>
          <ixy>1.76402e-10</ixy>
          <ixz>-1.8433e-10</ixz>
          <iyy>0.000166924</iyy>
          <iyz>-3.89845e-05</iyz>
          <izz>0.000103621</izz>
        </inertia>
      </inertial>
      <collision name='bot_slider_r_collision'>
        <pose>0 0 0 0 -0 0</pose>
        <geometry>
          <mesh>
            <scale>1 1 1</scale>
            <uri>model://AGV5/meshes/bot_slider_r.STL</uri>
          </mesh>
        </geometry>
      </collision>
      <visual name='bot_slider_r_visual'>
        <pose>0 0 0 0 -0 0</pose>
        <geometry>
          <mesh>
            <scale>1 1 1</scale>
            <uri>model://AGV5/meshes/bot_slider_r.STL</uri>
          </mesh>
        </geometry>
      </visual>
    </link>
    <joint name='sci_r_A_joint' type='revolute'>
      <pose relative_to='bot_slider_r'>0 0 0 0 -0 0</pose>
      <parent>bot_slider_r</parent>
      <child>sci_r_A</child>
      <axis>
        <xyz>-1 0 0</xyz>
        <limit>
          <lower>-10</lower>
          <upper>10</upper>
        </limit>
        <dynamics>
          <spring_reference>0</spring_reference>
          <spring_stiffness>0</spring_stiffness>
        </dynamics>
      </axis>
    </joint>
    <link name='sci_r_A'>
      <pose relative_to='sci_r_A_joint'>0 0 0 0 -0 0</pose>
      <inertial>
        <pose>-0.003208 0.231962 0.321605 0 -0 0</pose>
        <mass>0.674706</mass>
        <inertia>
          <ixx>0.0033198</ixx>
          <ixy>-2.584e-09</ixy>
          <ixz>3.02647e-09</ixz>
          <iyy>0.00225635</iyy>
          <iyz>-0.00145097</iyz>
          <izz>0.00138007</izz>
        </inertia>
      </inertial>
      <collision name='sci_r_A_collision'>
        <pose>0 0 0 0 -0 0</pose>
        <geometry>
          <mesh>
            <scale>1 1 1</scale>
            <uri>model://AGV5/meshes/sci_r_A.STL</uri>
          </mesh>
        </geometry>
      </collision>
      <visual name='sci_r_A_visual'>
        <pose>0 0 0 0 -0 0</pose>
        <geometry>
          <mesh>
            <scale>1 1 1</scale>
            <uri>model://AGV5/meshes/sci_r_A.STL</uri>
          </mesh>
        </geometry>
      </visual>
    </link>
    <joint name='sci_bolt_r_joint' type='revolute'>
      <pose relative_to='sci_r_A'>0 0.231068 0.320363 0 -0 0</pose>
      <parent>sci_r_A</parent>
      <child>sci_bolt_r</child>
      <axis>
        <xyz>1 0 0</xyz>
        <limit>
          <lower>-10</lower>
          <upper>10</upper>
        </limit>
        <dynamics>
          <spring_reference>0</spring_reference>
          <spring_stiffness>0</spring_stiffness>
        </dynamics>
      </axis>
    </joint>
    <link name='sci_bolt_r'>
      <pose relative_to='sci_bolt_r_joint'>0 0 0 0 -0 0</pose>
      <inertial>
        <pose>-0 0 -0 0 -0 0</pose>
        <mass>1.0709</mass>
        <inertia>
          <ixx>0.000255204</ixx>
          <ixy>-8.87798e-21</ixy>
          <ixz>-1.27282e-17</ixz>
          <iyy>0.000855782</iyy>
          <iyz>-2.79945e-20</iyz>
          <izz>0.000855782</izz>
        </inertia>
      </inertial>
      <collision name='sci_bolt_r_collision'>
        <pose>0 0 0 0 -0 0</pose>
        <geometry>
          <mesh>
            <scale>1 1 1</scale>
            <uri>model://AGV5/meshes/sci_bolt_r.STL</uri>
          </mesh>
        </geometry>
      </collision>
      <visual name='sci_bolt_r_visual'>
        <pose>0 0 0 0 -0 0</pose>
        <geometry>
          <mesh>
            <scale>1 1 1</scale>
            <uri>model://AGV5/meshes/sci_bolt_r.STL</uri>
          </mesh>
        </geometry>
      </visual>
    </link>
    <joint name='sci_r_B_joint' type='revolute'>
      <pose relative_to='sci_bolt_r'>0 0 0 0 -0 0</pose>
      <parent>sci_bolt_r</parent>
      <child>sci_r_B</child>
      <axis>
        <xyz>1 0 0</xyz>
        <limit>
          <lower>-10</lower>
          <upper>10</upper>
        </limit>
        <dynamics>
          <spring_reference>0</spring_reference>
          <spring_stiffness>0</spring_stiffness>
        </dynamics>
      </axis>
    </joint>
    <link name='sci_r_B'>
      <pose relative_to='sci_r_B_joint'>0 0 0 0 -0 0</pose>
      <inertial>
        <pose>0.003208 0.000894 -0.001241 0 -0 0</pose>
        <mass>0.674706</mass>
        <inertia>
          <ixx>0.0033198</ixx>
          <ixy>2.584e-09</ixy>
          <ixz>3.02647e-09</ixz>
          <iyy>0.00225635</iyy>
          <iyz>0.00145097</iyz>
          <izz>0.00138007</izz>
        </inertia>
      </inertial>
      <collision name='sci_r_B_collision'>
        <pose>0 0 0 0 -0 0</pose>
        <geometry>
          <mesh>
            <scale>1 1 1</scale>
            <uri>model://AGV5/meshes/sci_r_B.STL</uri>
          </mesh>
        </geometry>
      </collision>
      <visual name='sci_r_B_visual'>
        <pose>0 0 0 0 -0 0</pose>
        <geometry>
          <mesh>
            <scale>1 1 1</scale>
            <uri>model://AGV5/meshes/sci_r_B.STL</uri>
          </mesh>
        </geometry>
      </visual>
    </link>
    <joint name='virtual_base_r_joint' type='revolute'>
      <pose relative_to='sci_r_B'>0 -0.231068 0.320363 0 -0 0</pose>
      <parent>sci_r_B</parent>
      <child>base_link</child>
      <axis>
        <xyz>-1 0 0</xyz>
        <limit>
          <lower>-10</lower>
          <upper>10</upper>
        </limit>
        <dynamics>
          <spring_reference>0</spring_reference>
          <spring_stiffness>0</spring_stiffness>
        </dynamics>
      </axis>
    </joint>

    <!-- Add plugins to control the AGV-->
    <plugin name="diff_drive_controller" filename="libgazebo_ros_diff_drive.so">

      <!-- Plugin update rate in Hz -->
      <update_rate>50</update_rate>

      
      <left_joint>DW_L_joint</left_joint>
      <right_joint>DW_R_joint</right_joint>
      <wheel_Separation>0.465</wheel_Separation>
      <wheel_diameter>0.097</wheel_diameter>


      <max_wheel_acceleration>1.0</max_wheel_acceleration>
      <max_wheel_torque>20</max_wheel_torque>

    
      <odometry_topic>odom</odometry_topic>
      <odometry_frame>odom</odometry_frame>
      <robot_base_frame>base_footprint</robot_base_frame>

      <publish_odom>true</publish_odom>
      <publish_odom_tf>true</publish_odom_tf>
      <publish_wheel_tf>true</publish_wheel_tf>

    </plugin>

    <plugin name="object_controller" filename="libgazebo_ros_planar_move.so">
      <commandTopic>cmd_vel</commandTopic>
      <odometryTopic>odom</odometryTopic>
      <odometryFrame>odom</odometryFrame>
      <odometryRate>20.0</odometryRate>
      <robotBaseFrame>base_footprint</robotBaseFrame>
    </plugin>
    
  </model>
</sdf>
